Workbook

Sheet 실행-우진
A2: 관리번호 | C2: 순수 우진산전 제작시 | D2: 수량 | E2: PROJECT | F2: 미국 SEPTA-PROJECT 실행원가 | L2: 수주처 | M2: ㈜현대로템 | N2: 작성일자 | O2: 2010.08.19 강재준
A3: NO | B3: 제 품 명 | E3: 재료비① | G3: 노무비② | I3: 제조경비③ | K3: 제조원가④ (①+②+③) | L3: 판매관리비⑤ | M3: 총원가⑥ | N3: 이익⑦ | O3: 수주가⑧ | P3: 비 고
B4: 제품코드 | C4: 제 품 명 | E4: 재료비 | F4: 비율 | G4: 공수Hr | H4: 노무비 | I4: 비율 | J4: 제조경비 | L4: =$M$32 -> 0.12 | M4: (④+⑤) | N4: (⑧-⑥)
A5: 1 | B5: 10005980 | C5: (BZP)BUTTON BUZZER | D5: 1 | E5: 57980 | F5: =IF(ISERROR(E5/O5),"0",(E5/O5)) -> 0.64422222 | G5: 0.5 | H5: =G5*$M$31 -> 20479 | I5: =IF(ISERROR(J5/O5),"0",(J5/O5)) -> 0.079422222 | J5: =G5*$M$34 -> 7148 | K5: =E5+H5+J5 -> 85607 | L5: =K5*$M$32 -> 10272.84 | M5: =K5+L5 -> 95879.84 | N5: =O5-M5 -> -5879.84 | O5: 90000
A6: 2 | B6: 10005981 | C6: (DBZ)DOOR BUZZER ASS'Y | D6: 1 | E6: 37600 | F6: =IF(ISERROR(E6/O6),"0",(E6/O6)) -> 0.78333333 | G6: 0.2 | H6: =G6*$M$31 -> 8191.6 | I6: =IF(ISERROR(J6/O6),"0",(J6/O6)) -> 0.059566667 | J6: =G6*$M$34 -> 2859.2 | K6: =E6+H6+J6 -> 48650.8 | L6: =K6*$M$32 -> 5838.096 | M6: =K6+L6 -> 54488.896 | N6: =O6-M6 -> -6488.896 | O6: 48000
A7: 3 | B7: 10005982 | C7: (CSP)CAB SPEAKER ASS'Y | D7: 1 | E7: 101239 | F7: =IF(ISERROR(E7/O7),"0",(E7/O7)) -> 0.88033913 | G7: 0.5 | H7: =G7*$M$31 -> 20479 | I7: =IF(ISERROR(J7/O7),"0",(J7/O7)) -> 0.062156522 | J7: =G7*$M$34 -> 7148 | K7: =E7+H7+J7 -> 128866 | L7: =K7*$M$32 -> 15463.92 | M7: =K7+L7 -> 144329.92 | N7: =O7-M7 -> -29329.92 | O7: 115000
A8: 4 | B8: 10005983 | C8: (ISP)INTERIOR SPEAKER | D8: 1 | E8: 119982 | F8: =IF(ISERROR(E8/O8),"0",(E8/O8)) -> 0.61529231 | G8: 1 | H8: =G8*$M$31 -> 40958 | I8: =IF(ISERROR(J8/O8),"0",(J8/O8)) -> 0.073312821 | J8: =G8*$M$34 -> 14296 | K8: =E8+H8+J8 -> 175236 | L8: =K8*$M$32 -> 21028.32 | M8: =K8+L8 -> 196264.32 | N8: =O8-M8 -> -1264.32 | O8: 195000
A9: 5 | B9: 10005984 | C9: (ANSM)ANS MICROPHONE ASS'Y | D9: 1 | E9: 103170 | F9: =IF(ISERROR(E9/O9),"0",(E9/O9)) -> 0.429875 | G9: 1 | H9: =G9*$M$31 -> 40958 | I9: =IF(ISERROR(J9/O9),"0",(J9/O9)) -> 0.059566667 | J9: =G9*$M$34 -> 14296 | K9: =E9+H9+J9 -> 158424 | L9: =K9*$M$32 -> 19010.88 | M9: =K9+L9 -> 177434.88 | N9: =O9-M9 -> 62565.12 | O9: 240000
A10: 6 | B10: 10005986 | C10: (CRA)COMMUNICATION RACK A (1/2) | D10: 1 | E10: =13938122+470000+800000 -> 15208122 | F10: =IF(ISERROR(E10/O10),"0",(E10/O10)) -> 1.2364327 | G10: 9 | H10: =G10*$M$31 -> 368622 | I10: =IF(ISERROR(J10/O10),"0",(J10/O10)) -> 0.010460488 | J10: =G10*$M$34 -> 128664 | K10: =E10+H10+J10 -> 15705408 | L10: =K10*$M$32 -> 1884649 | M10: =K10+L10 -> 17590057 | N10: =O10-M10 -> -5290057 | O10: 12300000
A11: 7 | B11: 10005987 | C11: (CRB)COMMUNICATION RACK B (1/2) | D11: 1 | E11: 7435470 | F11: =IF(ISERROR(E11/O11),"0",(E11/O11)) -> 1.0472493 | G11: 9 | H11: =G11*$M$31 -> 368622 | I11: =IF(ISERROR(J11/O11),"0",(J11/O11)) -> 0.01812169 | J11: =G11*$M$34 -> 128664 | K11: =E11+H11+J11 -> 7932756 | L11: =K11*$M$32 -> 951930.72 | M11: =K11+L11 -> 8884686.7 | N11: =O11-M11 -> -1784686.7 | O11: 7100000
A12: 8 | B12: 10005988 | C12: (ESP)EXTERIOR SPEAKER | D12: 1 | E12: 56770 | F12: =IF(ISERROR(E12/O12),"0",(E12/O12)) -> 0.42051852 | G12: 0.5 | H12: =G12*$M$31 -> 20479 | I12: =IF(ISERROR(J12/O12),"0",(J12/O12)) -> 0.052948148 | J12: =G12*$M$34 -> 7148 | K12: =E12+H12+J12 -> 84397 | L12: =K12*$M$32 -> 10127.64 | M12: =K12+L12 -> 94524.64 | N12: =O12-M12 -> 40475.36 | O12: 135000
A13: 9 | B13: 10005989 | C13: (PID1)LCD PASSENGER INFORMATION ASS'Y | D13: 1 | E13: 1497015 | F13: =IF(ISERROR(E13/O13),"0",(E13/O13)) -> 0.831675 | G13: 4.5 | H13: =G13*$M$31 -> 184311 | I13: =IF(ISERROR(J13/O13),"0",(J13/O13)) -> 0.03574 | J13: =G13*$M$34 -> 64332 | K13: =E13+H13+J13 -> 1745658 | L13: =K13*$M$32 -> 209478.96 | M13: =K13+L13 -> 1955137 | N13: =O13-M13 -> -155136.96 | O13: 1800000
A14: 10 | B14: 10005990 | C14: (PID2)LCD PASSENGER INFORMATION DISPLAY | D14: 1 | E14: 1417387 | F14: =IF(ISERROR(E14/O14),"0",(E14/O14)) -> 0.78743722 | G14: 4.5 | H14: =G14*$M$31 -> 184311 | I14: =IF(ISERROR(J14/O14),"0",(J14/O14)) -> 0.03574 | J14: =G14*$M$34 -> 64332 | K14: =E14+H14+J14 -> 1666030 | L14: =K14*$M$32 -> 199923.6 | M14: =K14+L14 -> 1865953.6 | N14: =O14-M14 -> -65953.6 | O14: 1800000
A15: 11 | B15: 10005991 | C15: (PII)LED PASSENGER INFORMATION INDICATOR | D15: 1 | E15: 1340301 | F15: =IF(ISERROR(E15/O15),"0",(E15/O15)) -> 0.84829177 | G15: 8 | H15: =G15*$M$31 -> 327664 | I15: =IF(ISERROR(J15/O15),"0",(J15/O15)) -> 0.07238481 | J15: =G15*$M$34 -> 114368 | K15: =E15+H15+J15 -> 1782333 | L15: =K15*$M$32 -> 213879.96 | M15: =K15+L15 -> 1996213 | N15: =O15-M15 -> -416212.96 | O15: 1580000
A16: 12 | B16: 10005992 | C16: (FDI)LED FRONT DESTINATION SIGN | D16: 1 | E16: 1875077 | F16: =IF(ISERROR(E16/O16),"0",(E16/O16)) -> 0.89289381 | G16: 6.5 | H16: =G16*$M$31 -> 266227 | I16: =IF(ISERROR(J16/O16),"0",(J16/O16)) -> 0.044249524 | J16: =G16*$M$34 -> 92924 | K16: =E16+H16+J16 -> 2234228 | L16: =K16*$M$32 -> 268107.36 | M16: =K16+L16 -> 2502335.4 | N16: =O16-M16 -> -402335.36 | O16: 2100000
A17: 13 | B17: 10005993 | C17: (SDI)LED SIDE DESTINATION INDICATOR | D17: 1 | E17: 1634217 | F17: =IF(ISERROR(E17/O17),"0",(E17/O17)) -> 0.94066482 | G17: 6.5 | H17: =G17*$M$31 -> 266227 | I17: =IF(ISERROR(J17/O17),"0",(J17/O17)) -> 0.053487596 | J17: =G17*$M$34 -> 92924 | K17: =E17+H17+J17 -> 1993368 | L17: =K17*$M$32 -> 239204.16 | M17: =K17+L17 -> 2232572.2 | N17: =O17-M17 -> -495272.16 | O17: 1737300
A18: 14 | B18: 10005994 | C18: (TRA)ANTENNA CAB RADIO | D18: 1 | E18: 668000 | F18: =IF(ISERROR(E18/O18),"0",(E18/O18)) -> 0.23857143 | H18: =G18*$M$31 -> 0 | I18: =IF(ISERROR(J18/O18),"0",(J18/O18)) -> 0 | J18: =G18*$M$34 -> 0 | K18: =E18+H18+J18 -> 668000 | L18: =K18*$M$32 -> 80160 | M18: =K18+L18 -> 748160 | N18: =O18-M18 -> 2051840 | O18: 2800000
A19: 15 | B19: 10005995 | C19: (WGA)ANTENNA GPS | D19: 1 | E19: 1377040 | F19: =IF(ISERROR(E19/O19),"0",(E19/O19)) -> 0.99543141 | H19: =G19*$M$31 -> 0 | I19: =IF(ISERROR(J19/O19),"0",(J19/O19)) -> 0 | J19: =G19*$M$34 -> 0 | K19: =E19+H19+J19 -> 1377040 | L19: =K19*$M$32 -> 165244.8 | M19: =K19+L19 -> 1542284.8 | N19: =O19-M19 -> -158924.8 | O19: 1383360
A20: 16 | B20: 10005996 | C20: (TMP)CAB TEXT MASSAGE PRINTER | D20: 1 | E20: 2226302 | F20: =IF(ISERROR(E20/O20),"0",(E20/O20)) -> 0.8905208 | G20: 3 | H20: =G20*$M$31 -> 122874 | I20: =IF(ISERROR(J20/O20),"0",(J20/O20)) -> 0.0171552 | J20: =G20*$M$34 -> 42888 | K20: =E20+H20+J20 -> 2392064 | L20: =K20*$M$32 -> 287047.68 | M20: =K20+L20 -> 2679111.7 | N20: =O20-M20 -> -179111.68 | O20: 2500000
A21: 17 | B21: 10005997 | C21: (CCP)TERMINAL ATAS/AVL | D21: 1 | E21: 1938576 | F21: =IF(ISERROR(E21/O21),"0",(E21/O21)) -> 0.92313143 | G21: 2 | H21: =G21*$M$31 -> 81916 | I21: =IF(ISERROR(J21/O21),"0",(J21/O21)) -> 0.013615238 | J21: =G21*$M$34 -> 28592 | K21: =E21+H21+J21 -> 2049084 | L21: =K21*$M$32 -> 245890.08 | M21: =K21+L21 -> 2294974.1 | N21: =O21-M21 -> -194974.08 | O21: 2100000
A22: 18 | B22: 10005998 | C22: (CBZ)BUZZER COMMUNICATION | D22: 1 | E22: 224000 | F22: =IF(ISERROR(E22/O22),"0",(E22/O22)) -> 0.90909091 | H22: =G22*$M$31 -> 0 | I22: =IF(ISERROR(J22/O22),"0",(J22/O22)) -> 0 | J22: =G22*$M$34 -> 0 | K22: =E22+H22+J22 -> 224000 | L22: =K22*$M$32 -> 26880 | M22: =K22+L22 -> 250880 | N22: =O22-M22 -> -4480 | O22: 246400
A23: 19 | B23: 10005999 | C23: (TRF)TRANSFORMER | D23: 1 | E23: 82994 | F23: =IF(ISERROR(E23/O23),"0",(E23/O23)) -> 0.88361991 | G23: 1 | H23: =G23*$M$31 -> 40958 | I23: =IF(ISERROR(J23/O23),"0",(J23/O23)) -> 0.15220655 | J23: =G23*$M$34 -> 14296 | K23: =E23+H23+J23 -> 138248 | L23: =K23*$M$32 -> 16589.76 | M23: =K23+L23 -> 154837.76 | N23: =O23-M23 -> -60912.76 | O23: 93925
A24: 20 | B24: 10006095 | C24: (BZPB)BUZZER PUSH BUTTON BOX ASS'Y | D24: 1 | E24: 64980 | F24: =IF(ISERROR(E24/O24),"0",(E24/O24)) -> 0.722 | G24: 1 | H24: =G24*$M$31 -> 40958 | I24: =IF(ISERROR(J24/O24),"0",(J24/O24)) -> 0.15884444 | J24: =G24*$M$34 -> 14296 | K24: =E24+H24+J24 -> 120234 | L24: =K24*$M$32 -> 14428.08 | M24: =K24+L24 -> 134662.08 | N24: =O24-M24 -> -44662.08 | O24: 90000
A25: 21 | B25: 10006099 | C25: (TRB)TRAIN RADIO BRACKET | D25: 1 | E25: 18500 | F25: =IF(ISERROR(E25/O25),"0",(E25/O25)) -> 0 | H25: =G25*$M$31 -> 0 | I25: =IF(ISERROR(J25/O25),"0",(J25/O25)) -> 0 | J25: =G25*$M$34 -> 0 | K25: =E25+H25+J25 -> 18500 | L25: =K25*$M$32 -> 2220 | M25: =K25+L25 -> 20720 | N25: =O25-M25 -> -20720 | O25: 0
A26: 22 | B26: 10006241 | C26: (DMJ)DRIVER MICROPHONE JACK | D26: 1 | E26: 122580 | F26: =IF(ISERROR(E26/O26),"0",(E26/O26)) -> 0.681 | G26: 1 | H26: =G26*$M$31 -> 40958 | I26: =IF(ISERROR(J26/O26),"0",(J26/O26)) -> 0.079422222 | J26: =G26*$M$34 -> 14296 | K26: =E26+H26+J26 -> 177834 | L26: =K26*$M$32 -> 21340.08 | M26: =K26+L26 -> 199174.08 | N26: =O26-M26 -> -19174.08 | O26: 180000
A27: 23 | B27: 10006243 | C27: (JCR)JUMPER COUPLER | D27: 1 | E27: 4639800 | F27: =IF(ISERROR(E27/O27),"0",(E27/O27)) -> 0 | H27: =G27*$M$31 -> 0 | I27: =IF(ISERROR(J27/O27),"0",(J27/O27)) -> 0 | J27: =G27*$M$34 -> 0 | K27: =E27+H27+J27 -> 4639800 | L27: =K27*$M$32 -> 556776 | M27: =K27+L27 -> 5196576 | N27: =O27-M27 -> -5196576 | O27: 0
A28: 24 | C28: 터키 프로젝트 수주가 이관액 | F28: =IF(ISERROR(E28/O28),"0",(E28/O28)) -> 0 | H28: =G28*$M$31 -> 0 | I28: =IF(ISERROR(J28/O28),"0",(J28/O28)) -> 0 | J28: =G28*$M$34 -> 0 | K28: =E28+H28+J28 -> 0 | L28: =K28*$M$32 -> 0 | M28: =K28+L28 -> 0 | N28: =O28-M28 -> 0
A29: TOTAL | E29: =SUM(E5:E28) -> 42247102 | F29: =IF(ISERROR(E29/O29),"0",(E29/O29)) -> 0 | G29: =SUM(G5:G28) -> 59.7 | H29: =SUM(H5:H28) -> 2445192.6 | I29: =IF(ISERROR(J29/O29),"0",(J29/O29)) -> 0 | J29: =SUM(J5:J28) -> 853471.2 | K29: =SUM(K5:K28) -> 45545766 | L29: =SUM(L5:L28) -> 5465491.9 | M29: =SUM(M5:M28) -> 51011258 | N29: =SUM(N5:N28) -> -12377273
A30: ◆특이사항◆ | L30: 적용 기준가 | N30: 첨 부 | O30: 1.견적원가 산출 LIST
A31: 순수 우진제작시는 BA관련하여 PID1,2를 미국에서 조립하지 않고, 우진에서 조립했을경우를 말함 | L31: 1.임률(\/Hr) | M31: 40958
L32: 2.적용판관비 | M32: 0.12 | N32: 배포처 | P32: P.R.B팀 확인
L33: 3.적용 이익
L34: 4.제조임률 | M34: 14296
A35: P.R.F팀 | J35: ㈜우진산전 | P35: REV.00,A4

Sheet 실행-우진총
A2: 관리번호 | C2: 순수 우진산전 제작시 | D2: 수량 | E2: PROJECT | F2: 미국 SEPTA-PROJECT 실행원가 | L2: 수주처 | M2: ㈜현대로템 | N2: 작성일자 | O2: 2010.08.19 강재준
A3: NO | B3: 제 품 명 | E3: 재료비① | G3: 노무비② | I3: 제조경비③ | K3: 제조원가④ (①+②+③) | L3: 판매관리비⑤ | M3: 총원가⑥ | N3: 이익⑦ | O3: 수주가⑧ | P3: 비 고
B4: 제품코드 | C4: 제 품 명 | E4: 재료비 | F4: 비율 | G4: 공수Hr | H4: 노무비 | I4: 비율 | J4: 제조경비 | L4: =$M$32 -> 0.12 | M4: (④+⑤) | N4: (⑧-⑥)
A5: 1 | B5: 10005980 | C5: (BZP)BUTTON BUZZER | D5: =VLOOKUP($B5,[1]단품수량!$B$5:$M$27,12,FALSE) -> 720 | E5: =D5*'실행-우진'!E5 -> 41745600 | F5: =IF(ISERROR(E5/O5),"0",(E5/O5)) -> 0.64422222 | G5: =D5*'실행-우진'!G5 -> 360 | H5: =G5*$M$31 -> 14744880 | I5: =IF(ISERROR(J5/O5),"0",(J5/O5)) -> 0.079422222 | J5: =G5*$M$34 -> 5146560 | K5: =E5+H5+J5 -> 61637040 | L5: =K5*$M$32 -> 7396444.8 | M5: =K5+L5 -> 69033485 | N5: =O5-M5 -> -4233484.8 | O5: =D5*'실행-우진'!O5 -> 64800000
A6: 2 | B6: 10005981 | C6: (DBZ)DOOR BUZZER ASS'Y | D6: =VLOOKUP($B6,[1]단품수량!$B$5:$M$27,12,FALSE) -> 480 | E6: =D6*'실행-우진'!E6 -> 18048000 | F6: =IF(ISERROR(E6/O6),"0",(E6/O6)) -> 0.78333333 | G6: =D6*'실행-우진'!G6 -> 96 | H6: =G6*$M$31 -> 3931968 | I6: =IF(ISERROR(J6/O6),"0",(J6/O6)) -> 0.059566667 | J6: =G6*$M$34 -> 1372416 | K6: =E6+H6+J6 -> 23352384 | L6: =K6*$M$32 -> 2802286.1 | M6: =K6+L6 -> 26154670 | N6: =O6-M6 -> -3114670.1 | O6: =D6*'실행-우진'!O6 -> 23040000
A7: 3 | B7: 10005982 | C7: (CSP)CAB SPEAKER ASS'Y | D7: =VLOOKUP($B7,[1]단품수량!$B$5:$M$27,12,FALSE) -> 158 | E7: =D7*'실행-우진'!E7 -> 15995762 | F7: =IF(ISERROR(E7/O7),"0",(E7/O7)) -> 0.88033913 | G7: =D7*'실행-우진'!G7 -> 79 | H7: =G7*$M$31 -> 3235682 | I7: =IF(ISERROR(J7/O7),"0",(J7/O7)) -> 0.062156522 | J7: =G7*$M$34 -> 1129384 | K7: =E7+H7+J7 -> 20360828 | L7: =K7*$M$32 -> 2443299.4 | M7: =K7+L7 -> 22804127 | N7: =O7-M7 -> -4634127.4 | O7: =D7*'실행-우진'!O7 -> 18170000
A8: 4 | B8: 10005983 | C8: (ISP)INTERIOR SPEAKER | D8: =VLOOKUP($B8,[1]단품수량!$B$5:$M$27,12,FALSE) -> 960 | E8: =D8*'실행-우진'!E8 -> 115182720 | F8: =IF(ISERROR(E8/O8),"0",(E8/O8)) -> 0.61529231 | G8: =D8*'실행-우진'!G8 -> 960 | H8: =G8*$M$31 -> 39319680 | I8: =IF(ISERROR(J8/O8),"0",(J8/O8)) -> 0.073312821 | J8: =G8*$M$34 -> 13724160 | K8: =E8+H8+J8 -> 168226560 | L8: =K8*$M$32 -> 20187187 | M8: =K8+L8 -> 1.8841375e+08 | N8: =O8-M8 -> -1213747.2 | O8: =D8*'실행-우진'!O8 -> 187200000
A9: 5 | B9: 10005984 | C9: (ANSM)ANS MICROPHONE ASS'Y | D9: =VLOOKUP($B9,[1]단품수량!$B$5:$M$27,12,FALSE) -> 120 | E9: =D9*'실행-우진'!E9 -> 12380400 | F9: =IF(ISERROR(E9/O9),"0",(E9/O9)) -> 0.429875 | G9: =D9*'실행-우진'!G9 -> 120 | H9: =G9*$M$31 -> 4914960 | I9: =IF(ISERROR(J9/O9),"0",(J9/O9)) -> 0.059566667 | J9: =G9*$M$34 -> 1715520 | K9: =E9+H9+J9 -> 19010880 | L9: =K9*$M$32 -> 2281305.6 | M9: =K9+L9 -> 21292186 | N9: =O9-M9 -> 7507814.4 | O9: =D9*'실행-우진'!O9 -> 28800000
A10: 6 | B10: 10005986 | C10: (CRA)COMMUNICATION RACK A (1/2) | D10: =VLOOKUP($B10,[1]단품수량!$B$5:$M$27,12,FALSE) -> 79 | E10: =D10*'실행-우진'!E10 -> 1201441638 | F10: =IF(ISERROR(E10/O10),"0",(E10/O10)) -> 1.2364327 | G10: =D10*'실행-우진'!G10 -> 711 | H10: =G10*$M$31 -> 29121138 | I10: =IF(ISERROR(J10/O10),"0",(J10/O10)) -> 0.010460488 | J10: =G10*$M$34 -> 10164456 | K10: =E10+H10+J10 -> 1240727232 | L10: =K10*$M$32 -> 1.4888727e+08 | M10: =K10+L10 -> 1.3896145e+09 | N10: =O10-M10 -> -4.179145e+08 | O10: =D10*'실행-우진'!O10 -> 971700000
A11: 7 | B11: 10005987 | C11: (CRB)COMMUNICATION RACK B (1/2) | D11: =VLOOKUP($B11,[1]단품수량!$B$5:$M$27,12,FALSE) -> 79 | E11: =D11*'실행-우진'!E11 -> 587402130 | F11: =IF(ISERROR(E11/O11),"0",(E11/O11)) -> 1.0472493 | G11: =D11*'실행-우진'!G11 -> 711 | H11: =G11*$M$31 -> 29121138 | I11: =IF(ISERROR(J11/O11),"0",(J11/O11)) -> 0.01812169 | J11: =G11*$M$34 -> 10164456 | K11: =E11+H11+J11 -> 626687724 | L11: =K11*$M$32 -> 75202527 | M11: =K11+L11 -> 7.0189025e+08 | N11: =O11-M11 -> -1.4099025e+08 | O11: =D11*'실행-우진'!O11 -> 560900000
A12: 8 | B12: 10005988 | C12: (ESP)EXTERIOR SPEAKER | D12: =VLOOKUP($B12,[1]단품수량!$B$5:$M$27,12,FALSE) -> 480 | E12: =D12*'실행-우진'!E12 -> 27249600 | F12: =IF(ISERROR(E12/O12),"0",(E12/O12)) -> 0.42051852 | G12: =D12*'실행-우진'!G12 -> 240 | H12: =G12*$M$31 -> 9829920 | I12: =IF(ISERROR(J12/O12),"0",(J12/O12)) -> 0.052948148 | J12: =G12*$M$34 -> 3431040 | K12: =E12+H12+J12 -> 40510560 | L12: =K12*$M$32 -> 4861267.2 | M12: =K12+L12 -> 45371827 | N12: =O12-M12 -> 19428173 | O12: =D12*'실행-우진'!O12 -> 64800000
A13: 9 | B13: 10005989 | C13: (PID1)LCD PASSENGER INFORMATION ASS'Y | D13: =VLOOKUP($B13,[1]단품수량!$B$5:$M$27,12,FALSE) -> 480 | E13: =D13*'실행-우진'!E13 -> 718567200 | F13: =IF(ISERROR(E13/O13),"0",(E13/O13)) -> 0.831675 | G13: =D13*'실행-우진'!G13 -> 2160 | H13: =G13*$M$31 -> 88469280 | I13: =IF(ISERROR(J13/O13),"0",(J13/O13)) -> 0.03574 | J13: =G13*$M$34 -> 30879360 | K13: =E13+H13+J13 -> 837915840 | L13: =K13*$M$32 -> 1.005499e+08 | M13: =K13+L13 -> 9.3846574e+08 | N13: =O13-M13 -> -74465741 | O13: =D13*'실행-우진'!O13 -> 864000000
A14: 10 | B14: 10005990 | C14: (PID2)LCD PASSENGER INFORMATION DISPLAY | D14: =VLOOKUP($B14,[1]단품수량!$B$5:$M$27,12,FALSE) -> 240 | E14: =D14*'실행-우진'!E14 -> 340172880 | F14: =IF(ISERROR(E14/O14),"0",(E14/O14)) -> 0.78743722 | G14: =D14*'실행-우진'!G14 -> 1080 | H14: =G14*$M$31 -> 44234640 | I14: =IF(ISERROR(J14/O14),"0",(J14/O14)) -> 0.03574 | J14: =G14*$M$34 -> 15439680 | K14: =E14+H14+J14 -> 399847200 | L14: =K14*$M$32 -> 47981664 | M14: =K14+L14 -> 447828864 | N14: =O14-M14 -> -15828864 | O14: =D14*'실행-우진'!O14 -> 432000000
A15: 11 | B15: 10005991 | C15: (PII)LED PASSENGER INFORMATION INDICATOR | D15: =VLOOKUP($B15,[1]단품수량!$B$5:$M$27,12,FALSE) -> 240 | E15: =D15*'실행-우진'!E15 -> 321672240 | F15: =IF(ISERROR(E15/O15),"0",(E15/O15)) -> 0.84829177 | G15: =D15*'실행-우진'!G15 -> 1920 | H15: =G15*$M$31 -> 78639360 | I15: =IF(ISERROR(J15/O15),"0",(J15/O15)) -> 0.07238481 | J15: =G15*$M$34 -> 27448320 | K15: =E15+H15+J15 -> 427759920 | L15: =K15*$M$32 -> 51331190 | M15: =K15+L15 -> 4.7909111e+08 | N15: =O15-M15 -> -99891110 | O15: =D15*'실행-우진'!O15 -> 379200000
A16: 12 | B16: 10005992 | C16: (FDI)LED FRONT DESTINATION SIGN | D16: =VLOOKUP($B16,[1]단품수량!$B$5:$M$27,12,FALSE) -> 158 | E16: =D16*'실행-우진'!E16 -> 296262166 | F16: =IF(ISERROR(E16/O16),"0",(E16/O16)) -> 0.89289381 | G16: =D16*'실행-우진'!G16 -> 1027 | H16: =G16*$M$31 -> 42063866 | I16: =IF(ISERROR(J16/O16),"0",(J16/O16)) -> 0.044249524 | J16: =G16*$M$34 -> 14681992 | K16: =E16+H16+J16 -> 353008024 | L16: =K16*$M$32 -> 42360963 | M16: =K16+L16 -> 3.9536899e+08 | N16: =O16-M16 -> -63568987 | O16: =D16*'실행-우진'!O16 -> 331800000
... A27: 23 | B27: 10006243 | C27: (JCR)JUMPER COUPLER | D27: =VLOOKUP($B27,[1]단품수량!$B$5:$M$27,12,FALSE) -> 41 | E27: =D27*'실행-우진'!E27 -> 190231800 | F27: =IF(ISERROR(E27/O27),"0",(E27/O27)) -> 0 | G27: =D27*'실행-우진'!G27 -> 0 | H27: =G27*$M$31 -> 0 | I27: =IF(ISERROR(J27/O27),"0",(J27/O27)) -> 0 | J27: =G27*$M$34 -> 0 | K27: =E27+H27+J27 -> 190231800 | L27: =K27*$M$32 -> 22827816 | M27: =K27+L27 -> 213059616 | N27: =O27-M27 -> -213059616 | O27: =D27*'실행-우진'!O27 -> 0
A28: 24 | C28: 터키 프로젝트 수주가 이관액 | F28: =IF(ISERROR(E28/O28),"0",(E28/O28)) -> 0 | H28: =G28*$M$31 -> 0 | I28: =IF(ISERROR(J28/O28),"0",(J28/O28)) -> 0 | J28: =G28*$M$34 -> 0 | K28: =E28+H28+J28 -> 0 | L28: =K28*$M$32 -> 0 | M28: =K28+L28 -> 0 | N28: =O28-M28 -> 2000000000 | O28: 2000000000
A29: TOTAL | E29: =SUM(E5:E28) -> 5714970620 | F29: =IF(ISERROR(E29/O29),"0",(E29/O29)) -> 0.69366284 | G29: =SUM(G5:G28) -> 14328 | H29: =SUM(H5:H28) -> 586846224 | I29: =IF(ISERROR(J29/O29),"0",(J29/O29)) -> 0.024861913 | J29: =SUM(J5:J28) -> 204833088 | K29: =SUM(K5:K28) -> 6506649932 | L29: =SUM(L5:L28) -> 7.8079799e+08 | M29: =SUM(M5:M28) -> 7.2874479e+09 | N29: =SUM(N5:N28) -> 9.5138272e+08 | O29: =SUM(O5:O28) -> 8238830640
A30: ◆특이사항◆ | L30: 적용 기준가 | N30: 첨 부 | O30: 1.견적원가 산출 LIST
L31: 1.임률(\/Hr) | M31: 40958
L32: 2.적용판관비 | M32: 0.12 | N32: 배포처 | P32: P.R.B팀 확인
L33: 3.적용 이익
L34: 4.제조임률 | M34: 14296
A35: P.R.F팀 | J35: ㈜우진산전 | P35: REV.00,A4

Sheet Sheet1
A1: SEPTA 프로젝트 원가분석 (순수우진제작 VS BA충족시) | N1: 우진산전 제작시의 단가 금액
A2: 제품코드 | B2: 제품명 | C2: NO | D2: LEVEL | E2: 품목코드 | F2: 도면번호 | G2: 군 | H2: 품명 | I2: 규격/재질 | J2: 수량 | K2: SET | L2: 총량 | M2: 조달 | N2: 화폐 | O2: 단가 | P2: 금액 | Q2: 구매처
A3: 10005984 | B3: =VLOOKUP(A3,[1]단품수량!$B$5:$E$27,4,FALSE) -> ANSM | C3: 1 | D3: 01.__.__.__.__.__.__ | E3: 30120744 | F3: R1D1361-21500( b)(1) | H3: BRACKET | I3: ASS'Y/ | J3: 1 | K3: 1 | L3: =VLOOKUP(A3,[1]단품수량!$B$5:$P$27,13,FALSE)*K3 -> 120 | M3: 외작 | N3: ￦ | O3: 8000 | P3: =K3*O3 -> 8000 | Q3: 보성엔지니어링
A4: 10005984 | B4: =VLOOKUP(A4,[1]단품수량!$B$5:$E$27,4,FALSE) -> ANSM | C4: 2 | D4: 02.__.__.__.__.__.__ | E4: 30120745 | F4: R1D1361-21500( b)(2) | H4: MIC CAP | I4: ASS'Y/ | J4: 1 | K4: 1 | L4: =VLOOKUP(A4,[1]단품수량!$B$5:$P$27,13,FALSE)*K4 -> 120 | M4: 외작 | N4: ￦ | O4: 800 | P4: =K4*O4 -> 800 | Q4: 보성엔지니어링
A5: 10005984 | B5: =VLOOKUP(A5,[1]단품수량!$B$5:$E$27,4,FALSE) -> ANSM | C5: 3 | D5: 03.__.__.__.__.__.__ | E5: 30062576 | H5: GRAND | I5: PG7/ASS'Y | J5: 1 | K5: 1 | L5: =VLOOKUP(A5,[1]단품수량!$B$5:$P$27,13,FALSE)*K5 -> 120 | M5: 내자 | N5: ￦ | O5: 660 | P5: =K5*O5 -> 660 | Q5: 은강반도체
A6: 10005984 | B6: =VLOOKUP(A6,[1]단품수량!$B$5:$E$27,4,FALSE) -> ANSM | C6: 4 | D6: 04.__.__.__.__.__.__ | E6: 30120230 | H6: MICRO PHONE | I6: AOM-4544P-2R/ | J6: 1 | K6: 1 | L6: =VLOOKUP(A6,[1]단품수량!$B$5:$P$27,13,FALSE)*K6 -> 120 | M6: 내자 | N6: ￦ | O6: 2000 | P6: =K6*O6 -> 2000 | Q6: 은강반도체
A7: 10005984 | B7: =VLOOKUP(A7,[1]단품수량!$B$5:$E$27,4,FALSE) -> ANSM | C7: 5 | D7: 05.__.__.__.__.__.__ | E7: 30118557 | H7: CONNECTOR(7PIN PLUG) | I7: FRITS4106F14S-07SB0F6/ | J7: 1 | K7: 1 | L7: =VLOOKUP(A7,[1]단품수량!$B$5:$P$27,13,FALSE)*K7 -> 120 | M7: 외자 | N7: ￦ | O7: 38900 | P7: =K7*O7 -> 38900 | Q7: 햄머
A8: 10005984 | B8: =VLOOKUP(A8,[1]단품수량!$B$5:$E$27,4,FALSE) -> ANSM | C8: 6 | D8: 06.__.__.__.__.__.__ | E8: 30118570 | H8: SOCKET(16s SIZE) | I8: 10-40552G117/ | J8: 7 | K8: 7 | L8: =VLOOKUP(A8,[1]단품수량!$B$5:$P$27,13,FALSE)*K8 -> 840 | M8: 외자 | N8: ￦ | O8: 900 | P8: =K8*O8 -> 6300 | Q8: 햄머
A9: 10005984 | B9: =VLOOKUP(A9,[1]단품수량!$B$5:$E$27,4,FALSE) -> ANSM | C9: 7 | D9: 07.__.__.__.__.__.__ | E9: 30118545 | H9: CONNECTOR(7 PIN RECEP) | I9: FRITS4100F14S-07PB0G1F6/ | J9: 1 | K9: 1 | L9: =VLOOKUP(A9,[1]단품수량!$B$5:$P$27,13,FALSE)*K9 -> 120 | M9: 외자 | N9: ￦ | O9: 37400 | P9: =K9*O9 -> 37400 | Q9: 햄머
A10: 10005984 | B10: =VLOOKUP(A10,[1]단품수량!$B$5:$E$27,4,FALSE) -> ANSM | C10: 8 | D10: 08.__.__.__.__.__.__ | E10: 30118572 | H10: PIN(16s SIZE) | I10: 10-40553G117/ | J10: 7 | K10: 7 | L10: =VLOOKUP(A10,[1]단품수량!$B$5:$P$27,13,FALSE)*K10 -> 840 | M10: 외자 | N10: ￦ | O10: 400 | P10: =K10*O10 -> 2800 | Q10: 햄머
A11: 10005984 | B11: =VLOOKUP(A11,[1]단품수량!$B$5:$E$27,4,FALSE) -> ANSM | C11: 9 | D11: 09.__.__.__.__.__.__ | E11: 30118569 | H11: SEALING PLUG | I11: 10-305045-16/ | J11: 8 | K11: 8 | L11: =VLOOKUP(A11,[1]단품수량!$B$5:$P$27,13,FALSE)*K11 -> 960 | M11: 외자 | N11: ￦ | O11: 400 | P11: =K11*O11 -> 3200 | Q11: 햄머
A12: 10005984 | B12: =VLOOKUP(A12,[1]단품수량!$B$5:$E$27,4,FALSE) -> ANSM | C12: 10 | D12: 10.__.__.__.__.__.__ | E12: 30120660 | F12: R1D1359-21672( c)(12) | H12: NAME PLATE | I12: ANSM/ | J12: 1 | K12: 1 | L12: =VLOOKUP(A12,[1]단품수량!$B$5:$P$27,13,FALSE)*K12 -> 120 | M12: 외작 | N12: ￦ | O12: 600 | P12: =K12*O12 -> 600 | Q12: 구영에스피(주)
A13: 10005984 | B13: =VLOOKUP(A13,[1]단품수량!$B$5:$E$27,4,FALSE) -> ANSM | C13: 11 | D13: 11.__.__.__.__.__.__ | E13: 30093304 | H13: CABLE | I13: 100G1121-0.75-2/6/ASS'Y | J13: 1 | K13: 1 | L13: =VLOOKUP(A13,[1]단품수량!$B$5:$P$27,13,FALSE)*K13 -> 120 | M13: 외자 | N13: ￦ | O13: 2510 | P13: =K13*O13 -> 2510 | Q13: 햄머
A14: 10005980 | B14: =VLOOKUP(A14,[1]단품수량!$B$5:$E$27,4,FALSE) -> BZP | C14: 12 | D14: 01.__.__.__.__.__.__ | E14: 30120742 | F14: R1D1357-21417( b)(1) | H14: BRACKET | I14: ASS'Y/ | J14: 1 | K14: 1 | L14: =VLOOKUP(A14,[1]단품수량!$B$5:$P$27,13,FALSE)*K14 -> 720 | M14: 외작 | N14: ￦ | O14: 11000 | P14: =K14*O14 -> 11000 | Q14: 보성엔지니어링
A15: 10005980 | B15: =VLOOKUP(A15,[1]단품수량!$B$5:$E$27,4,FALSE) -> BZP | C15: 13 | D15: 02.__.__.__.__.__.__ | E15: 30120743 | F15: R1D1357-21417( b)(2) | H15: RUBBER GASKET | I15: EDPM t1.0/ | J15: 1 | K15: 1 | L15: =VLOOKUP(A15,[1]단품수량!$B$5:$P$27,13,FALSE)*K15 -> 720 | M15: 외작 | N15: ￦ | O15: 500 | P15: =K15*O15 -> 500 | Q15: 명진전기
A16: 10005980 | B16: =VLOOKUP(A16,[1]단품수량!$B$5:$E$27,4,FALSE) -> BZP | C16: 14 | D16: 03.__.__.__.__.__.__ | E16: 30118497 | H16: SWITCH | I16: AV22LP404/ | J16: 1 | K16: 1 | L16: =VLOOKUP(A16,[1]단품수량!$B$5:$P$27,13,FALSE)*K16 -> 720 | M16: 내자 | N16: ￦ | O16: 43000 | P16: =K16*O16 -> 43000 | Q16: 이지파워
A17: 10005980 | B17: =VLOOKUP(A17,[1]단품수량!$B$5:$E$27,4,FALSE) -> BZP | C17: 15 | D17: 04.__.__.__.__.__.__ | E17: 30094283 | H17: CONNECTOR | I17: 770-203(RECEP)/ASS'Y | J17: 1 | K17: 1 | L17: =VLOOKUP(A17,[1]단품수량!$B$5:$P$27,13,FALSE)*K17 -> 720 | M17: 외자 | N17: ￦ | O17: 1300 | P17: =K17*O17 -> 1300 | Q17: 만희기전(주)
A18: 10005980 | B18: =VLOOKUP(A18,[1]단품수량!$B$5:$E$27,4,FALSE) -> BZP | C18: 16 | D18: 05.__.__.__.__.__.__ | E18: 30094282 | H18: CONNECTOR | I18: 770-213(RECEP)/ASS'Y | J18: 1 | K18: 1 | L18: =VLOOKUP(A18,[1]단품수량!$B$5:$P$27,13,FALSE)*K18 -> 720 | M18: 외자 | N18: ￦ | O18: 1100 | P18: =K18*O18 -> 1100 | Q18: 만희기전(주)
A19: 10005980 | B19: =VLOOKUP(A19,[1]단품수량!$B$5:$E$27,4,FALSE) -> BZP | C19: 17 | D19: 06.__.__.__.__.__.__ | E19: 30120654 | F19: R1D1359-21672( c)(6) | H19: NAME PLATE | I19: BZP/ | J19: 1 | K19: 1 | L19: =VLOOKUP(A19,[1]단품수량!$B$5:$P$27,13,FALSE)*K19 -> 720 | M19: 외작 | N19: ￦ | O19: 600 | P19: =K19*O19 -> 600 | Q19: 구영에스피(주)
A20: 10005980 | B20: =VLOOKUP(A20,[1]단품수량!$B$5:$E$27,4,FALSE) -> BZP | C20: 18 | D20: 07.__.__.__.__.__.__ | E20: 30063371 | H20: WIRE | I20: 100G0111-1.50-0/ | J20: 1 | K20: 1 | L20: =VLOOKUP(A20,[1]단품수량!$B$5:$P$27,13,FALSE)*K20 -> 720 | M20: 외자 | N20: ￦ | O20: 480 | P20: =K20*O20 -> 480 | Q20: 햄머
A21: 10006095 | B21: =VLOOKUP(A21,[1]단품수량!$B$5:$E$27,4,FALSE) -> BZPB | C21: 19 | D21: 01.__.__.__.__.__.__ | E21: 30120776 | H21: PUSH BUTTON SWITCH | I21: IFS3Z1A20/ | J21: 1 | K21: 1 | L21: =VLOOKUP(A21,[1]단품수량!$B$5:$P$27,13,FALSE)*K21 -> 316 | M21: 내자 | N21: ￦ | O21: 13500 | P21: =K21*O21 -> 13500 | Q21: 이지파워
A22: 10006095 | B22: =VLOOKUP(A22,[1]단품수량!$B$5:$E$27,4,FALSE) -> BZPB | C22: 20 | D22: 02.__.__.__.__.__.__ | E22: 30120739 | F22: R1D1357-21414( a) | H22: FRAME ASS'Y | I22: ASS'Y/ | J22: 1 | K22: 1 | L22: =VLOOKUP(A22,[1]단품수량!$B$5:$P$27,13,FALSE)*K22 -> 316 | M22: 외작 | N22: ￦ | O22: 48000 | P22: =K22*O22 -> 48000 | Q22: 보성엔지니어링
A23: 10006095 | B23: =VLOOKUP(A23,[1]단품수량!$B$5:$E$27,4,FALSE) -> BZPB | C23: 21 | D23: __.01.__.__.__.__.__ | E23: 30120737 | F23: R1D1357-21412( a) | H23: FRAME | I23: ASS'Y/ | J23: 1 | K23: 1 | L23: =VLOOKUP(A23,[1]단품수량!$B$5:$P$27,13,FALSE)*K23 -> 316 | M23: 외작 | N23: ￦ | O23: 0 | P23: =K23*O23 -> 0 | Q23: 보성엔지니어링
A24: 10006095 | B24: =VLOOKUP(A24,[1]단품수량!$B$5:$E$27,4,FALSE) -> BZPB | C24: 22 | D24: __.02.__.__.__.__.__ | E24: 30120738 | F24: R1D1357-21413( a) | H24: FRAME | I24: ASS'Y/ | J24: 1 | K24: 1 | L24: =VLOOKUP(A24,[1]단품수량!$B$5:$P$27,13,FALSE)*K24 -> 316 | M24: 외작 | N24: ￦ | O24: 0 | P24: =K24*O24 -> 0 | Q24: 보성엔지니어링
A25: 10006095 | B25: =VLOOKUP(A25,[1]단품수량!$B$5:$E$27,4,FALSE) -> BZPB | C25: 23 | D25: 03.__.__.__.__.__.__ | E25: 30120740 | F25: R1D1357-21415 | H25: BRACKET | I25: ASS'Y/ | J25: 1 | K25: 1 | L25: =VLOOKUP(A25,[1]단품수량!$B$5:$P$27,13,FALSE)*K25 -> 316 | M25: 외작 | N25: ￦ | O25: 0 | P25: =K25*O25 -> 0 | Q25: 보성엔지니어링
A26: 10006095 | B26: =VLOOKUP(A26,[1]단품수량!$B$5:$E$27,4,FALSE) -> BZPB | C26: 24 | D26: 04.__.__.__.__.__.__ | E26: 30094283 | H26: CONNECTOR | I26: 770-203(RECEP)/ASS'Y | J26: 1 | K26: 1 | L26: =VLOOKUP(A26,[1]단품수량!$B$5:$P$27,13,FALSE)*K26 -> 316 | M26: 외자 | N26: ￦ | O26: 1300 | P26: =K26*O26 -> 1300 | Q26: 만희기전(주)
A27: 10006095 | B27: =VLOOKUP(A27,[1]단품수량!$B$5:$E$27,4,FALSE) -> BZPB | C27: 25 | D27: 05.__.__.__.__.__.__ | E27: 30094282 | H27: CONNECTOR | I27: 770-213(RECEP)/ASS'Y | J27: 1 | K27: 1 | L27: =VLOOKUP(A27,[1]단품수량!$B$5:$P$27,13,FALSE)*K27 -> 316 | M27: 외자 | N27: ￦ | O27: 1100 | P27: =K27*O27 -> 1100 | Q27: 만희기전(주)
A28: 10006095 | B28: =VLOOKUP(A28,[1]단품수량!$B$5:$E$27,4,FALSE) -> BZPB | C28: 26 | D28: 06.__.__.__.__.__.__ | E28: 30120653 | F28: R1D1359-21672( c)(5) | H28: NAME PLATE | I28: BZPB/ | J28: 1 | K28: 1 | L28: =VLOOKUP(A28,[1]단품수량!$B$5:$P$27,13,FALSE)*K28 -> 316 | M28: 외작 | N28: ￦ | O28: 600 | P28: =K28*O28 -> 600 | Q28: 구영에스피(주)
A29: 10006095 | B29: =VLOOKUP(A29,[1]단품수량!$B$5:$E$27,4,FALSE) -> BZPB | C29: 27 | D29: 07.__.__.__.__.__.__ | E29: 30063371 | H29: WIRE | I29: 100G0111-1.50-0/ | J29: 1 | K29: 1 | L29: =VLOOKUP(A29,[1]단품수량!$B$5:$P$27,13,FALSE)*K29 -> 316 | M29: 외자 | N29: ￦ | O29: 480 | P29: =K29*O29 -> 480 | Q29: 햄머
A30: 10005998 | B30: =VLOOKUP(A30,[1]단품수량!$B$5:$E$27,4,FALSE) -> CBZ | C30: 28 | D30: 01.__.__.__.__.__.__ | E30: 10005998 | H30: (CBZ)BUZZER COMMUNICATION | J30: 1 | K30: 1 | L30: =VLOOKUP(A30,[1]단품수량!$B$5:$P$27,13,FALSE)*K30 -> 357 | M30: 외작 | N30: ￦ | O30: 224000 | P30: =K30*O30 -> 224000 | Q30: 이지파워
A31: 10005997 | B31: =VLOOKUP(A31,[1]단품수량!$B$5:$E$27,4,FALSE) -> CCP | C31: 29 | D31: 01.__.__.__.__.__.__ | E31: 30120714 | F31: R1D1362-21508( b) | H31: FRAME ASS'Y | I31: ASS'Y/ | J31: 1 | K31: 1 | L31: =VLOOKUP(A31,[1]단품수량!$B$5:$P$27,13,FALSE)*K31 -> 158 | M31: 외작 | N31: ￦ | O31: 75000 | P31: =K31*O31 -> 75000 | Q31: 세일ENGINEERING
A32: 10005997 | B32: =VLOOKUP(A32,[1]단품수량!$B$5:$E$27,4,FALSE) -> CCP | C32: 30 | D32: __.01.__.__.__.__.__ | E32: 30120715 | F32: R1D1362-21509( a) | H32: PLATE | I32: ASS'Y/ | J32: 1 | K32: 1 | L32: =VLOOKUP(A32,[1]단품수량!$B$5:$P$27,13,FALSE)*K32 -> 158 | M32: 외작 | N32: ￦ | O32: 0 | P32: =K32*O32 -> 0 | Q32: 세일ENGINEERING
A33: 10005997 | B33: =VLOOKUP(A33,[1]단품수량!$B$5:$E$27,4,FALSE) -> CCP | C33: 31 | D33: __.02.__.__.__.__.__ | E33: 30120716 | F33: R1D1362-21510( b) | H33: PLATE | I33: ASS'Y/ | J33: 1 | K33: 1 | L33: =VLOOKUP(A33,[1]단품수량!$B$5:$P$27,13,FALSE)*K33 -> 158 | M33: 외작 | N33: ￦ | O33: 0 | P33: =K33*O33 -> 0 | Q33: 세일ENGINEERING
A34: 10005997 | B34: =VLOOKUP(A34,[1]단품수량!$B$5:$E$27,4,FALSE) -> CCP | C34: 32 | D34: 02.__.__.__.__.__.__ | E34: 30120718 | F34: R1D1362-21512 | H34: BRACKET | I34: ASS'Y/ | J34: 1 | K34: 1 | L34: =VLOOKUP(A34,[1]단품수량!$B$5:$P$27,13,FALSE)*K34 -> 158 | M34: 외작 | N34: ￦ | O34: 0 | P34: =K34*O34 -> 0 | Q34: 세일ENGINEERING
A35: 10005997 | B35: =VLOOKUP(A35,[1]단품수량!$B$5:$E$27,4,FALSE) -> CCP | C35: 33 | D35: 03.__.__.__.__.__.__ | E35: 30120765 | H35: TOUCH SCREEN UNIT | I35: MN070000ACD 7Inch WIDE/ | J35: 1 | K35: 1 | L35: =VLOOKUP(A35,[1]단품수량!$B$5:$P$27,13,FALSE)*K35 -> 158 | M35: 내자 | N35: ￦ | O35: 10000 | P35: =K35*O35 -> 10000 | Q35: 동도테크(주)
A36: 10005997 | B36: =VLOOKUP(A36,[1]단품수량!$B$5:$E$27,4,FALSE) -> CCP | C36: 34 | D36: 04.__.__.__.__.__.__ | E36: 30120766 | H36: TFT-LCD UNIT | I36: LMS700KF05/ | J36: 1 | K36: 1 | L36: =VLOOKUP(A36,[1]단품수량!$B$5:$P$27,13,FALSE)*K36 -> 158 | M36: 내자 | N36: ￦ | O36: 70000 | P36: =K36*O36 -> 70000 | Q36: 동도테크(주)
A37: 10005997 | B37: =VLOOKUP(A37,[1]단품수량!$B$5:$E$27,4,FALSE) -> CCP | C37: 35 | D37: 05.__.__.__.__.__.__ | E37: 30120717 | F37: R1D1362-21511( c) | H37: COVER | I37: ASS'Y/ | J37: 1 | K37: 1 | L37: =VLOOKUP(A37,[1]단품수량!$B$5:$P$27,13,FALSE)*K37 -> 158 | M37: 외작 | N37: ￦ | O37: 0 | P37: =K37*O37 -> 0 | Q37: 세일ENGINEERING
A38: 10005997 | B38: =VLOOKUP(A38,[1]단품수량!$B$5:$E$27,4,FALSE) -> CCP | C38: 36 | D38: 06.__.__.__.__.__.__ | E38: 30118555 | H38: CONNECTOR(19PIN RECEP) | I38: FRITS4102R22-14PB0G1F6/ | J38: 1 | K38: 1 | L38: =VLOOKUP(A38,[1]단품수량!$B$5:$P$27,13,FALSE)*K38 -> 158 | M38: 외자 | N38: ￦ | O38: 23900 | P38: =K38*O38 -> 23900 | Q38: 햄머
A39: 10005997 | B39: =VLOOKUP(A39,[1]단품수량!$B$5:$E$27,4,FALSE) -> CCP | C39: 37 | D39: 07.__.__.__.__.__.__ | E39: 30118583 | H39: CONNECTOR(19PIN 90PLUG) | I39: FRITS4108F22-14SB0F6/ | J39: 1 | K39: 1 | L39: =VLOOKUP(A39,[1]단품수량!$B$5:$P$27,13,FALSE)*K39 -> 158 | M39: 외자 | N39: ￦ | O39: 59800 | P39: =K39*O39 -> 59800 | Q39: 햄머
A40: 10005997 | B40: =VLOOKUP(A40,[1]단품수량!$B$5:$E$27,4,FALSE) -> CCP | C40: 38 | D40: 08.__.__.__.__.__.__ | E40: 30120669 | F40: R1D1359-21673(7) | H40: NAME PLATE | I40: CCP/ | J40: 1 | K40: 1 | L40: =VLOOKUP(A40,[1]단품수량!$B$5:$P$27,13,FALSE)*K40 -> 158 | M40: 외작 | N40: ￦ | O40: 1400 | P40: =K40*O40 -> 1400 | Q40: 구영에스피(주)
...
