Workbook

Sheet Sheet1
A1: SEPTA 프로젝트 원가분석 (순수우진제작 VS BA충족시)
A2: 제품코드 | B2: 제품명 | C2: NO | D2: LEVEL | E2: 품목코드 | F2: 도면번호 | G2: 군 | H2: 품명 | I2: 규격/재질 | J2: 수량 | K2: SET | L2: 총량 | M2: 조달 | N2: 구매처
A3: 10005984 | B3: =VLOOKUP(A3,[1]단품수량!$B$5:$E$27,4,FALSE) -> ANSM | C3: 1 | D3: 01.__.__.__.__.__.__ | E3: 30120744 | F3: R1D1361-21500( b)(1) | H3: BRACKET | I3: ASS'Y/ | J3: 1 | K3: 1 | L3: =VLOOKUP(A3,[1]단품수량!$B$5:$P$27,13,FALSE)*K3 -> 120 | M3: 외작 | N3: 보성엔지니어링
A4: 10005984 | B4: =VLOOKUP(A4,[1]단품수량!$B$5:$E$27,4,FALSE) -> ANSM | C4: 2 | D4: 02.__.__.__.__.__.__ | E4: 30120745 | F4: R1D1361-21500( b)(2) | H4: MIC CAP | I4: ASS'Y/ | J4: 1 | K4: 1 | L4: =VLOOKUP(A4,[1]단품수량!$B$5:$P$27,13,FALSE)*K4 -> 120 | M4: 외작 | N4: 보성엔지니어링
A5: 10005984 | B5: =VLOOKUP(A5,[1]단품수량!$B$5:$E$27,4,FALSE) -> ANSM | C5: 3 | D5: 03.__.__.__.__.__.__ | E5: 30062576 | H5: GRAND | I5: PG7/ASS'Y | J5: 1 | K5: 1 | L5: =VLOOKUP(A5,[1]단품수량!$B$5:$P$27,13,FALSE)*K5 -> 120 | M5: 내자 | N5: 은강반도체
A6: 10005984 | B6: =VLOOKUP(A6,[1]단품수량!$B$5:$E$27,4,FALSE) -> ANSM | C6: 4 | D6: 04.__.__.__.__.__.__ | E6: 30120230 | H6: MICRO PHONE | I6: AOM-4544P-2R/ | J6: 1 | K6: 1 | L6: =VLOOKUP(A6,[1]단품수량!$B$5:$P$27,13,FALSE)*K6 -> 120 | M6: 내자 | N6: 은강반도체
A7: 10005984 | B7: =VLOOKUP(A7,[1]단품수량!$B$5:$E$27,4,FALSE) -> ANSM | C7: 5 | D7: 05.__.__.__.__.__.__ | E7: 30118557 | H7: CONNECTOR(7PIN PLUG) | I7: FRITS4106F14S-07SB0F6/ | J7: 1 | K7: 1 | L7: =VLOOKUP(A7,[1]단품수량!$B$5:$P$27,13,FALSE)*K7 -> 120 | M7: 외자 | N7: 햄머
A8: 10005984 | B8: =VLOOKUP(A8,[1]단품수량!$B$5:$E$27,4,FALSE) -> ANSM | C8: 6 | D8: 06.__.__.__.__.__.__ | E8: 30118570 | H8: SOCKET(16s SIZE) | I8: 10-40552G117/ | J8: 7 | K8: 7 | L8: =VLOOKUP(A8,[1]단품수량!$B$5:$P$27,13,FALSE)*K8 -> 840 | M8: 외자 | N8: 햄머
A9: 10005984 | B9: =VLOOKUP(A9,[1]단품수량!$B$5:$E$27,4,FALSE) -> ANSM | C9: 7 | D9: 07.__.__.__.__.__.__ | E9: 30118545 | H9: CONNECTOR(7 PIN RECEP) | I9: FRITS4100F14S-07PB0G1F6/ | J9: 1 | K9: 1 | L9: =VLOOKUP(A9,[1]단품수량!$B$5:$P$27,13,FALSE)*K9 -> 120 | M9: 외자 | N9: 햄머
A10: 10005984 | B10: =VLOOKUP(A10,[1]단품수량!$B$5:$E$27,4,FALSE) -> ANSM | C10: 8 | D10: 08.__.__.__.__.__.__ | E10: 30118572 | H10: PIN(16s SIZE) | I10: 10-40553G117/ | J10: 7 | K10: 7 | L10: =VLOOKUP(A10,[1]단품수량!$B$5:$P$27,13,FALSE)*K10 -> 840 | M10: 외자 | N10: 햄머
A11: 10005984 | B11: =VLOOKUP(A11,[1]단품수량!$B$5:$E$27,4,FALSE) -> ANSM | C11: 9 | D11: 09.__.__.__.__.__.__ | E11: 30118569 | H11: SEALING PLUG | I11: 10-305045-16/ | J11: 8 | K11: 8 | L11: =VLOOKUP(A11,[1]단품수량!$B$5:$P$27,13,FALSE)*K11 -> 960 | M11: 외자 | N11: 햄머
A12: 10005984 | B12: =VLOOKUP(A12,[1]단품수량!$B$5:$E$27,4,FALSE) -> ANSM | C12: 10 | D12: 10.__.__.__.__.__.__ | E12: 30120660 | F12: R1D1359-21672( c)(12) | H12: NAME PLATE | I12: ANSM/ | J12: 1 | K12: 1 | L12: =VLOOKUP(A12,[1]단품수량!$B$5:$P$27,13,FALSE)*K12 -> 120 | M12: 외작 | N12: 구영에스피(주)
A13: 10005984 | B13: =VLOOKUP(A13,[1]단품수량!$B$5:$E$27,4,FALSE) -> ANSM | C13: 11 | D13: 11.__.__.__.__.__.__ | E13: 30093304 | H13: CABLE | I13: 100G1121-0.75-2/6/ASS'Y | J13: 1 | K13: 1 | L13: =VLOOKUP(A13,[1]단품수량!$B$5:$P$27,13,FALSE)*K13 -> 120 | M13: 외자 | N13: 햄머
A14: 10005997 | B14: =VLOOKUP(A14,[1]단품수량!$B$5:$E$27,4,FALSE) -> CCP | C14: 29 | D14: 01.__.__.__.__.__.__ | E14: 30120714 | F14: R1D1362-21508( b) | H14: FRAME ASS'Y | I14: ASS'Y/ | J14: 1 | K14: 1 | L14: =VLOOKUP(A14,[1]단품수량!$B$5:$P$27,13,FALSE)*K14 -> 158 | M14: 외작 | N14: 세일ENGINEERING
A15: 10005997 | B15: =VLOOKUP(A15,[1]단품수량!$B$5:$E$27,4,FALSE) -> CCP | C15: 30 | D15: __.01.__.__.__.__.__ | E15: 30120715 | F15: R1D1362-21509( a) | H15: PLATE | I15: ASS'Y/ | J15: 1 | K15: 1 | L15: =VLOOKUP(A15,[1]단품수량!$B$5:$P$27,13,FALSE)*K15 -> 158 | M15: 외작 | N15: 세일ENGINEERING
A16: 10005997 | B16: =VLOOKUP(A16,[1]단품수량!$B$5:$E$27,4,FALSE) -> CCP | C16: 31 | D16: __.02.__.__.__.__.__ | E16: 30120716 | F16: R1D1362-21510( b) | H16: PLATE | I16: ASS'Y/ | J16: 1 | K16: 1 | L16: =VLOOKUP(A16,[1]단품수량!$B$5:$P$27,13,FALSE)*K16 -> 158 | M16: 외작 | N16: 세일ENGINEERING
A17: 10005997 | B17: =VLOOKUP(A17,[1]단품수량!$B$5:$E$27,4,FALSE) -> CCP | C17: 32 | D17: 02.__.__.__.__.__.__ | E17: 30120718 | F17: R1D1362-21512 | H17: BRACKET | I17: ASS'Y/ | J17: 1 | K17: 1 | L17: =VLOOKUP(A17,[1]단품수량!$B$5:$P$27,13,FALSE)*K17 -> 158 | M17: 외작 | N17: 세일ENGINEERING
A18: 10005997 | B18: =VLOOKUP(A18,[1]단품수량!$B$5:$E$27,4,FALSE) -> CCP | C18: 33 | D18: 03.__.__.__.__.__.__ | E18: 30120765 | H18: TOUCH SCREEN UNIT | I18: MN070000ACD 7Inch WIDE/ | J18: 1 | K18: 1 | L18: =VLOOKUP(A18,[1]단품수량!$B$5:$P$27,13,FALSE)*K18 -> 158 | M18: 내자 | N18: 동도테크(주)
A19: 10005997 | B19: =VLOOKUP(A19,[1]단품수량!$B$5:$E$27,4,FALSE) -> CCP | C19: 34 | D19: 04.__.__.__.__.__.__ | E19: 30120766 | H19: TFT-LCD UNIT | I19: LMS700KF05/ | J19: 1 | K19: 1 | L19: =VLOOKUP(A19,[1]단품수량!$B$5:$P$27,13,FALSE)*K19 -> 158 | M19: 내자 | N19: 동도테크(주)
A20: 10005997 | B20: =VLOOKUP(A20,[1]단품수량!$B$5:$E$27,4,FALSE) -> CCP | C20: 35 | D20: 05.__.__.__.__.__.__ | E20: 30120717 | F20: R1D1362-21511( c) | H20: COVER | I20: ASS'Y/ | J20: 1 | K20: 1 | L20: =VLOOKUP(A20,[1]단품수량!$B$5:$P$27,13,FALSE)*K20 -> 158 | M20: 외작 | N20: 세일ENGINEERING
A21: 10005997 | B21: =VLOOKUP(A21,[1]단품수량!$B$5:$E$27,4,FALSE) -> CCP | C21: 36 | D21: 06.__.__.__.__.__.__ | E21: 30118555 | H21: CONNECTOR(19PIN RECEP) | I21: FRITS4102R22-14PB0G1F6/ | J21: 1 | K21: 1 | L21: =VLOOKUP(A21,[1]단품수량!$B$5:$P$27,13,FALSE)*K21 -> 158 | M21: 외자 | N21: 햄머
A22: 10005997 | B22: =VLOOKUP(A22,[1]단품수량!$B$5:$E$27,4,FALSE) -> CCP | C22: 37 | D22: 07.__.__.__.__.__.__ | E22: 30118583 | H22: CONNECTOR(19PIN 90PLUG) | I22: FRITS4108F22-14SB0F6/ | J22: 1 | K22: 1 | L22: =VLOOKUP(A22,[1]단품수량!$B$5:$P$27,13,FALSE)*K22 -> 158 | M22: 외자 | N22: 햄머
A23: 10005997 | B23: =VLOOKUP(A23,[1]단품수량!$B$5:$E$27,4,FALSE) -> CCP | C23: 38 | D23: 08.__.__.__.__.__.__ | E23: 30120669 | F23: R1D1359-21673(7) | H23: NAME PLATE | I23: CCP/ | J23: 1 | K23: 1 | L23: =VLOOKUP(A23,[1]단품수량!$B$5:$P$27,13,FALSE)*K23 -> 158 | M23: 외작 | N23: 구영에스피(주)
A24: 10005997 | B24: =VLOOKUP(A24,[1]단품수량!$B$5:$E$27,4,FALSE) -> CCP | C24: 39 | D24: 09.__.__.__.__.__.__ | E24: 30118569 | H24: SEALING PLUG | I24: 10-305045-16/ | J24: 6 | K24: 6 | L24: =VLOOKUP(A24,[1]단품수량!$B$5:$P$27,13,FALSE)*K24 -> 948 | M24: 외자 | N24: 햄머
A25: 10005997 | B25: =VLOOKUP(A25,[1]단품수량!$B$5:$E$27,4,FALSE) -> CCP | C25: 40 | D25: 10.__.__.__.__.__.__ | E25: 30118573 | H25: SOCKET(16 SIZE) | I25: 10-40556G117/ | J25: 19 | K25: 19 | L25: =VLOOKUP(A25,[1]단품수량!$B$5:$P$27,13,FALSE)*K25 -> 3002 | M25: 외자 | N25: 햄머
A26: 10005997 | B26: =VLOOKUP(A26,[1]단품수량!$B$5:$E$27,4,FALSE) -> CCP | C26: 41 | D26: 11.__.__.__.__.__.__ | E26: 30118582 | H26: PIN(16 SIZE) | I26: 10-40557G117/ | J26: 4 | K26: 4 | L26: =VLOOKUP(A26,[1]단품수량!$B$5:$P$27,13,FALSE)*K26 -> 632 | M26: 외자 | N26: 햄머
A27: 10005997 | B27: =VLOOKUP(A27,[1]단품수량!$B$5:$E$27,4,FALSE) -> CCP | C27: 42 | D27: 12.__.__.__.__.__.__ | E27: 30118581 | H27: PIN(16 SIZE SMALL) | I27: 10-40557-13G117/ | J27: 15 | K27: 15 | L27: =VLOOKUP(A27,[1]단품수량!$B$5:$P$27,13,FALSE)*K27 -> 2370 | M27: 외자 | N27: 햄머
A28: 10005997 | B28: =VLOOKUP(A28,[1]단품수량!$B$5:$E$27,4,FALSE) -> CCP | C28: 43 | D28: 13.__.__.__.__.__.__ | E28: 30120835 | H28: CCP CONTROL BOARD | I28: ASS'Y/ | J28: 1 | K28: 1 | L28: =VLOOKUP(A28,[1]단품수량!$B$5:$P$27,13,FALSE)*K28 -> 158 | M28: 외작 | N28: 동도테크(주)
A29: 10005997 | B29: =VLOOKUP(A29,[1]단품수량!$B$5:$E$27,4,FALSE) -> CCP | C29: 44 | D29: __.01.__.__.__.__.__ | E29: 30120992 | H29: IC | I29: MAX1480ECEPI/ | J29: 1 | K29: 1 | L29: =VLOOKUP(A29,[1]단품수량!$B$5:$P$27,13,FALSE)*K29 -> 158 | M29: 외자 | N29: 위니프로(주)
A30: 10005997 | B30: =VLOOKUP(A30,[1]단품수량!$B$5:$E$27,4,FALSE) -> CCP | C30: 45 | D30: __.02.__.__.__.__.__ | E30: 30121672 | H30: IC SOCKET | I30: 28P-WIDE/금도금사양 | J30: 1 | K30: 1 | L30: =VLOOKUP(A30,[1]단품수량!$B$5:$P$27,13,FALSE)*K30 -> 158 | M30: 내자 | N30: 위니프로(주)
A31: 10005997 | B31: =VLOOKUP(A31,[1]단품수량!$B$5:$E$27,4,FALSE) -> CCP | C31: 46 | D31: 14.__.__.__.__.__.__ | E31: 30120836 | H31: MICRO SPEAKER | I31: R1508RiW15(0.5W, 8Ω)/ | J31: 1 | K31: 1 | L31: =VLOOKUP(A31,[1]단품수량!$B$5:$P$27,13,FALSE)*K31 -> 158 | M31: 내자 | N31: 은강반도체
A32: 10005997 | B32: =VLOOKUP(A32,[1]단품수량!$B$5:$E$27,4,FALSE) -> CCP | C32: 47 | D32: 15.__.__.__.__.__.__ | E32: 30120837 | H32: CCP POWER BOARD | I32: WMS150B-12 Rev.A0// | J32: 1 | K32: 1 | L32: =VLOOKUP(A32,[1]단품수량!$B$5:$P$27,13,FALSE)*K32 -> 158 | M32: 외작 | N32: 이지파워
A33: 10005997 | B33: =VLOOKUP(A33,[1]단품수량!$B$5:$E$27,4,FALSE) -> CCP | C33: 48 | D33: 16.__.__.__.__.__.__ | E33: 20061700 | F33: R1D1355-22141 | H33: WIRING DIAGRAM | I33: CCP WIRING DIAGRAM/ | J33: 1 | K33: 1 | L33: =VLOOKUP(A33,[1]단품수량!$B$5:$P$27,13,FALSE)*K33 -> 158 | M33: 내작
A34: 10005997 | B34: =VLOOKUP(A34,[1]단품수량!$B$5:$E$27,4,FALSE) -> CCP | C34: 49 | D34: __.01.__.__.__.__.__ | E34: 30075140 | H34: WIRE | I34: 100G0111-0.75-0/ | J34: 1 | K34: 1 | L34: =VLOOKUP(A34,[1]단품수량!$B$5:$P$27,13,FALSE)*K34 -> 158 | M34: 외자 | N34: 햄머
A35: 10005997 | B35: =VLOOKUP(A35,[1]단품수량!$B$5:$E$27,4,FALSE) -> CCP | C35: 50 | D35: __.02.__.__.__.__.__ | E35: 30054014 | H35: WIRE | I35: 100G0111-0.5-0/ | J35: 2 | K35: 2 | L35: =VLOOKUP(A35,[1]단품수량!$B$5:$P$27,13,FALSE)*K35 -> 316 | M35: 내자 | N35: 햄머
A36: 10005997 | B36: =VLOOKUP(A36,[1]단품수량!$B$5:$E$27,4,FALSE) -> CCP | C36: 51 | D36: __.03.__.__.__.__.__ | E36: 30121474 | H36: WIRE | I36: 100G1121-0.5-2/6/ | J36: 1 | K36: 1 | L36: =VLOOKUP(A36,[1]단품수량!$B$5:$P$27,13,FALSE)*K36 -> 158 | M36: 외자 | N36: 햄머
A37: 10005997 | B37: =VLOOKUP(A37,[1]단품수량!$B$5:$E$27,4,FALSE) -> CCP | C37: 52 | D37: __.04.__.__.__.__.__ | E37: 30100325 | H37: PLUG | I37: 5557-06R/ | J37: 1 | K37: 1 | L37: =VLOOKUP(A37,[1]단품수량!$B$5:$P$27,13,FALSE)*K37 -> 158 | M37: 외자 | N37: 은강반도체
A38: 10005997 | B38: =VLOOKUP(A38,[1]단품수량!$B$5:$E$27,4,FALSE) -> CCP | C38: 53 | D38: __.05.__.__.__.__.__ | E38: 30115073 | H38: CONNECTOR | I38: 5557-04R/ | J38: 1 | K38: 1 | L38: =VLOOKUP(A38,[1]단품수량!$B$5:$P$27,13,FALSE)*K38 -> 158 | M38: 내자 | N38: 은강반도체
A39: 10005997 | B39: =VLOOKUP(A39,[1]단품수량!$B$5:$E$27,4,FALSE) -> CCP | C39: 54 | D39: __.06.__.__.__.__.__ | E39: 30081231 | H39: TERMINAL | I39: 5556, AWG18-24/ | J39: 10 | K39: 10 | L39: =VLOOKUP(A39,[1]단품수량!$B$5:$P$27,13,FALSE)*K39 -> 1580 | M39: 외자 | N39: 은강반도체
A40: 10005997 | B40: =VLOOKUP(A40,[1]단품수량!$B$5:$E$27,4,FALSE) -> CCP | C40: 55 | D40: __.07.__.__.__.__.__ | E40: 30118485 | H40: HOUSING | I40: SMH250-16V/ | J40: 1 | K40: 1 | L40: =VLOOKUP(A40,[1]단품수량!$B$5:$P$27,13,FALSE)*K40 -> 158 | M40: 내자 | N40: 은강반도체
...
