Workbook

Sheet 총합계
A1: PROJ. 명 | C1: 덴버전동차 50량 | J1: 원가견적/조사서(갑) - ASSY 用 - | T1: 회 사 명 (코드) | X1: 주) 우 진 산 전
A2: 차 종 | T2: 2011 년 4 월 11 일
A3: 품 번 | J3: 수 량 | N3: 50 | T3: 결 재 | U3: 담 당 | W3: 과장 | Y3: 팀장 | AA3: 임원
A5: 품 명 | C5: 방송, 표시기 | J5: 도 면 NO
A6: 구 성 부 품 비 명 세 | B6: NO | C6: 부 번 | G6: 부 품 명 | M6: 단 위 | N6: 수 량 | O6: 단 가 | Q6: 견 적 가 | W6: 조사가
Q7: 자작 | S7: 외주 | U7: 수입 | W7: 자작 | Y7: 외주 | AA7: 수입
B8: 1 | C8: ASS'Y | G8: =CRA!C5 -> CRA | M8: EA | N8: =CRA!N3 -> 50 | O8: =ROUND(CRA!G44,-3) -> 21021000 | Q8: 28763000 | S8: =N8*O8 -> 1051050000 | U8: =Q8*N8 -> 1438150000 | W8: =O8-Q8 -> -7742000 | Y8: =S8-U8 -> -387100000
B9: 2 | C9: ASS'Y | G9: =CCP!C5 -> CCP | M9: =CCP!M8 -> EA | N9: =CCP!N3 -> 50 | O9: =ROUND(CCP!G44,-3) -> 4904000 | Q9: 2373000 | S9: =N9*O9 -> 245200000 | U9: =Q9*N9 -> 118650000 | W9: =O9-Q9 -> 2531000 | Y9: =S9-U9 -> 126550000
B10: 3 | C10: ASS'Y | G10: =AAR!C5 -> AAR | M10: =AAR!M9 -> EA | N10: =AAR!N3 -> 50 | O10: =ROUND(AAR!G44,-3) -> 6994000 | Q10: 17223000 | S10: =N10*O10 -> 349700000 | U10: =Q10*N10 -> 861150000 | W10: =O10-Q10 -> -10229000 | Y10: =S10-U10 -> -511450000
B11: 4 | C11: ASS'Y | G11: =DPO!C5 -> DPO | M11: EA | N11: =DPO!N3 -> 50 | O11: =ROUND(DPO!G44,-3) -> 4827000 | Q11: 3253000 | S11: =N11*O11 -> 241350000 | U11: =Q11*N11 -> 162650000 | W11: =O11-Q11 -> 1574000 | Y11: =S11-U11 -> 78700000
B12: 5 | C12: ASS'Y | G12: =DMA!C5 -> DMA | M12: EA | N12: =DMA!N3 -> 50 | O12: =ROUND(DMA!G44,-3) -> 826000 | Q12: 592000 | S12: =N12*O12 -> 41300000 | U12: =Q12*N12 -> 29600000 | W12: =O12-Q12 -> 234000 | Y12: =S12-U12 -> 11700000
B13: 6 | C13: ASS'Y | G13: =CSP!C5 -> CSP | M13: EA | N13: =CSP!N3 -> 50 | O13: =ROUND(CSP!G44,-3) -> 471000 | Q13: 328000 | S13: =N13*O13 -> 23550000 | U13: =Q13*N13 -> 16400000 | W13: =O13-Q13 -> 143000 | Y13: =S13-U13 -> 7150000
B14: 7 | C14: ASS'Y | G14: =CPO!C5 -> CPO | M14: EA | N14: 100 | O14: =ROUND(CPO!G44,-3) -> 4595000 | Q14: 2613000 | S14: =N14*O14 -> 459500000 | U14: =Q14*N14 -> 261300000 | W14: =O14-Q14 -> 1982000 | Y14: =S14-U14 -> 198200000
B15: 8 | C15: ASS'Y | G15: =PEI!C5 -> PEI | M15: EA | N15: 100 | O15: =ROUND(PEI!G44,-3) -> 3791000 | Q15: 3860000 | S15: =N15*O15 -> 379100000 | U15: =Q15*N15 -> 386000000 | W15: =O15-Q15 -> -69000 | Y15: =S15-U15 -> -6900000
B16: 9 | C16: ASS'Y | G16: =ISP!C5 -> ISP | M16: EA | N16: 400 | O16: =ROUND(ISP!G44,-3) -> 463000 | Q16: 438000 | S16: =N16*O16 -> 185200000 | U16: =Q16*N16 -> 175200000 | W16: =O16-Q16 -> 25000 | Y16: =S16-U16 -> 10000000
B17: 10 | C17: ASS'Y | G17: =ESP!C5 -> ESP | M17: EA | N17: 200 | O17: =ROUND(ESP!G44,-3) -> 436000 | Q17: 325000 | S17: =N17*O17 -> 87200000 | U17: =Q17*N17 -> 65000000 | W17: =O17-Q17 -> 111000 | Y17: =S17-U17 -> 22200000
B18: 11 | C18: ASS'Y | G18: ='TRF1'!C5 -> TRF1 | M18: EA | N18: 200 | O18: =ROUND('TRF1'!G44,-3) -> 387000 | Q18: 404000 | S18: =N18*O18 -> 77400000 | U18: =Q18*N18 -> 80800000 | W18: =O18-Q18 -> -17000 | Y18: =S18-U18 -> -3400000
B19: 12 | C19: ASS'Y | G19: ='TRF2'!C5 -> TRF2 | M19: EA | N19: 100 | O19: =ROUND('TRF2'!G44,-3) -> 315000 | Q19: 614000 | S19: =N19*O19 -> 31500000 | U19: =Q19*N19 -> 61400000 | W19: =O19-Q19 -> -299000 | Y19: =S19-U19 -> -29900000
B20: 13 | C20: ASS'Y | G20: =FDI!C5 -> FDI | M20: EA | N20: 50 | O20: =ROUND(FDI!G44,-3) -> 4506000 | Q20: 2552000 | S20: =N20*O20 -> 225300000 | U20: =Q20*N20 -> 127600000 | W20: =O20-Q20 -> 1954000 | Y20: =S20-U20 -> 97700000
B21: 14 | C21: ASS'Y | G21: =SDI!C5 -> SDI | M21: EA | N21: 200 | O21: =ROUND(SDI!G44,-3) -> 4146000 | Q21: 2738000 | S21: =N21*O21 -> 829200000 | U21: =Q21*N21 -> 547600000 | W21: =O21-Q21 -> 1408000 | Y21: =S21-U21 -> 281600000
B22: 15 | C22: ASS'Y | G22: =PII!C5 -> PII | M22: EA | N22: 100 | O22: =ROUND(PII!G44,-3) -> 3346000 | Q22: 3688000 | S22: =N22*O22 -> 334600000 | U22: =Q22*N22 -> 368800000 | W22: =O22-Q22 -> -342000 | Y22: =S22-U22 -> -34200000
B23: 16 | C23: ASS'Y | G23: =PID!C5 -> PID | M23: EA | N23: 300 | O23: =ROUND(PID!G44,-3) -> 4088000 | Q23: 2788000 | S23: =N23*O23 -> 1226400000 | U23: =Q23*N23 -> 836400000 | W23: =O23-Q23 -> 1300000 | Y23: =S23-U23 -> 390000000
B24: 17 | C24: ASS'Y | G24: ='JCR1'!C5 -> JCR1 | M24: EA | N24: 25 | O24: =ROUND('JCR1'!G44,-3) -> 2886000 | Q24: 2788000 | S24: =N24*O24 -> 72150000 | U24: =Q24*N24 -> 69700000 | W24: =O24-Q24 -> 98000 | Y24: =S24-U24 -> 2450000
B25: 18 | C25: ASS'Y | G25: ='CBL1'!C5 -> CBL1 | M25: EA | N25: ='CBL1'!N3 -> 50 | O25: =ROUND('CBL1'!G44,-3) -> 6832000 | Q25: 7000 | S25: =N25*O25 -> 341600000 | U25: =Q25*N25 -> 350000 | W25: =O25-Q25 -> 6825000 | Y25: =S25-U25 -> 341250000
B26: 19 | C26: ASS'Y | G26: ='JCR2'!C5 -> JCR2 | M26: EA | N26: 25 | O26: =ROUND('JCR2'!G44,-3) -> 618000 | Q26: 0 | S26: =N26*O26 -> 15450000 | U26: =Q26*N26 -> 0 | W26: =O26-Q26 -> 618000 | Y26: =S26-U26 -> 15450000
B27: 20 | C27: ASS'Y | G27: ='CBL2'!C5 -> CBL2 | M27: EA | N27: ='CBL2'!N3 -> 50 | O27: =ROUND('CBL2'!G44,-3) -> 646000 | Q27: =249000+194000 -> 443000 | S27: =N27*O27 -> 32300000 | U27: =Q27*N27 -> 22150000 | W27: =O27-Q27 -> 203000 | Y27: =S27-U27 -> 10150000
Q28: =SUM(Q8:R27) -> 75790000 | S28: =SUM(S8:T27) -> 6249050000 | U28: =SUM(U8:V27) -> 5628900000 | Y28: =SUM(Y8:Z27) -> 620150000
A29: 원 가 항 목 | G29: 견 적 가 | J29: 조 사 가 | M29: 종 합 조 립 가 공 비 명 세 | N29: 공 정 명 | Q29: 조립시간 (HR) | S29: 가동임율 (￦/HR) | U29: 조립 가공비 | W29: 조립시간 (HR) | Y29: 가동임율 (￦/HR) | AA29: 조립 가공비
A30: 1 | C30: 자 작 | G30: =Q28 -> 75790000
A31: 2 | C31: 외 주 | G31: =S28+S87 -> 6549050000
A32: 3 | C32: 수 입 | G32: =U28 -> 5628900000
A33: 4 | C33: 재 료 비 | G33: =(G30+G31+G32) -> 12253740000
A34: 5 | C34: 노 무 비 | G34: =U38 -> 0
A35: 6 | C35: 경 비 | G35: =G34*0.1 -> 0
A36: 7 | C36: 가공비 | G36: =G34+G35 -> 0
A37: 8 | B37: 제조원가 | G37: =G33+G36 -> 12253740000
A38: 9 | B38: 재료관리비 | G38: 0 | U38: =SUM(U31:V37) -> 0
A39: 10 | B39: 판매 / 관리비 | G39: =G36*0.15 -> 0 | M39: 특기사항
A40: 11 | B40: 이 윤 | G40: =(G36+G39)*0.15 -> 0
A41: 12 | B41: 운반비 / PLT | G41: 0 | M41: 1. 환경시험비용 포함
...

Sheet CRA
A1: PROJ. 명 | C1: =총합계!C1 -> 덴버전동차 50량 | J1: 원가견적/조사서(갑) - ASSY 用 - | T1: 회 사 명 (코드) | X1: 주) 우 진 산 전
A2: 차 종 | T2: =총합계!T2 -> 2011 년 4 월 11 일
A3: 품 번 | J3: 수 량 | N3: 50 | T3: 결 재 | U3: 담 당 | W3: 과장 | Y3: 팀장 | AA3: 임원
A5: 품 명 | C5: CRA | J5: 도 면 NO
A6: 구 성 부 품 비 명 세 | B6: NO | C6: 부 번 | G6: 부 품 명 | M6: 단 위 | N6: 수 량 | O6: 단 가 | Q6: 견 적 가 | W6: 조사가
Q7: 자작 | S7: 외주 | U7: 수입 | W7: 자작 | Y7: 외주 | AA7: 수입
B8: 1 | C8: CPU BOARD | G8: SCB(RF-COM) | M8: EA | N8: 1 | O8: 400000 | S8: =N8*O8 -> 400000
B9: 2 | G9: LIC(WOOJIN) | M9: EA | N9: 1 | O9: 1350000 | S9: =N9*O9 -> 1350000
B10: 3 | G10: WLR(ANTS) | M10: EA | N10: 1 | O10: 350000 | S10: =N10*O10 -> 350000
B11: 4 | G11: VTX(ANTS) | M11: EA | N11: 1 | O11: 750000 | S11: =N11*O11 -> 750000
B12: 5 | G12: HDD-PCB(ANTS) | M12: EA | N12: 1 | O12: 800000 | S12: =N12*O12 -> 800000
B13: 6 | G13: CNCS-메인보드(ANTS) | M13: EA | N13: 1 | O13: 660000 | S13: =N13*O13 -> 660000
B14: 7 | G14: CNCS-CPU(i-Tech) | M14: EA | N14: 1 | O14: 2500000 | S14: =N14*O14 -> 2500000
B15: 8 | G15: BPB(ANTS) | M15: EA | N15: 1 | O15: 800000 | S15: =N15*O15 -> 800000
B16: 9 | G16: PAC-INT(RF-COM) | M16: EA | N16: 1 | O16: 580000 | S16: =N16*O16 -> 580000
B17: 10 | G17: PAC-MCU(RF-COM) | M17: EA | N17: 1 | O17: 580000 | S17: =N17*O17 -> 580000
B18: 11 | G18: PAC-VOL(RF-COM) | M18: EA | N18: 1 | O18: 580000 | S18: =N18*O18 -> 580000
B19: 12 | G19: PAC-485(RF-COM) | M19: EA | N19: 1 | O19: 995000 | S19: =N19*O19 -> 995000
B20: 13 | G20: PAC-VOIP(RF-COM) | M20: EA | N20: 1 | O20: 1903500 | S20: =N20*O20 -> 1903500
B21: 14 | G21: PAC-REC(RF_COM) | M21: EA | N21: 1 | O21: =928800*1.5 -> 1393200 | S21: =N21*O21 -> 1393200
B22: 15 | C22: POWER UNIT | G22: DC37.5V(이즈파워) | M22: EA | N22: 1 | O22: 1632000 | S22: =N22*O22 -> 1632000
B23: 16 | C23: FRAME BOX | G23: ASS'Y(USK) | M23: EA | N23: 1 | O23: 1555200 | S23: =N23*O23 -> 1555200
B24: 17 | C24: CONNECTOR | G24: AMP(엠비콘넥터) | M24: EA | N24: 1 | O24: 58050 | S24: =N24*O24 -> 58050
B25: 18 | C25: CONNECTOR | G25: Glenair ASS'Y(넥서스) | M25: EA | N25: 1 | O25: 218700 | S25: =N25*O25 -> 218700
B26: 19 | C26: MAX1480ECEPI(통신첩) | G26: ASS'Y(위니프로) | M26: EA | N26: 8 | O26: =33750*1.3 -> 43875 | S26: =N26*O26 -> 351000
B27: 20 | C27: Windows Xp 라이샌스 | G27: ASS'Y(i-Tech) | M27: EA | N27: 1 | O27: 137700 | S27: =N27*O27 -> 137700
Q28: =SUM(Q8:R27) -> 0 | S28: =SUM(S8:T27) -> 17594350 | U28: =SUM(U8:V27) -> 0
A29: 원 가 항 목 | G29: 견 적 가 | J29: 조 사 가 | M29: 종 합 조 립 가 공 비 명 세 | N29: 공 정 명 | Q29: 조립시간 (HR) | S29: 가동임율 (￦/HR) | U29: 조립 가공비 | W29: 조립시간 (HR) | Y29: 가동임율 (￦/HR) | AA29: 조립 가공비
A30: 1 | C30: 자 작 | G30: =Q28 -> 0
A31: 2 | C31: 외 주 | G31: =S28+S87 -> 17682100 | N31: 기기조립 | Q31: 25 | S31: 24000 | U31: =S31*Q31 -> 600000
A32: 3 | C32: 수 입 | G32: =U28 -> 0 | N32: 기기배선 | Q32: 36 | S32: 24000 | U32: =S32*Q32 -> 864000
A33: 4 | C33: 재 료 비 | G33: =(G30+G31+G32) -> 17682100 | N33: 검 사 | Q33: 14 | S33: 24000 | U33: =S33*Q33 -> 336000
A34: 5 | C34: 노 무 비 | G34: =U38 -> 1800000
A35: 6 | C35: 경 비 | G35: =G34*0.1 -> 180000
A36: 7 | C36: 가공비 | G36: =G34+G35 -> 1980000
A37: 8 | B37: 제조원가 | G37: =G33+G36 -> 19662100
A38: 9 | B38: 재료관리비 | G38: =((G30*0.01)+(G31*0.01)+(G32*0.02)) -> 176821 | U38: =SUM(U31:V37) -> 1800000
A39: 10 | B39: 판매 / 관리비 | G39: =G36*0.15 -> 297000 | M39: 특기사항
A40: 11 | B40: 이 윤 | G40: =(G36+G39)*0.15 -> 341550
A41: 12 | B41: 운반비 / PLT | G41: 30000
...

Sheet CCP
A1: PROJ. 명 | C1: =총합계!C1 -> 덴버전동차 50량 | J1: 원가견적/조사서(갑) - ASSY 用 - | T1: 회 사 명 (코드) | X1: 주) 우 진 산 전
A2: 차 종 | T2: =총합계!T2 -> 2011 년 4 월 11 일
A3: 품 번 | J3: 수 량 | N3: 50 | T3: 결 재 | U3: 담 당 | W3: 과장 | Y3: 팀장 | AA3: 임원
A5: 품 명 | C5: CCP | J5: 도 면 NO
A6: 구 성 부 품 비 명 세 | B6: NO | C6: 부 번 | G6: 부 품 명 | M6: 단 위 | N6: 수 량 | O6: 단 가 | Q6: 견 적 가 | W6: 조사가
Q7: 자작 | S7: 외주 | U7: 수입 | W7: 자작 | Y7: 외주 | AA7: 수입
B8: 1 | C8: CPU BOARD | G8: ASS'Y(woojin) | M8: EA | N8: 1 | O8: =1620000*1.4 -> 2268000 | S8: =N8*O8 -> 2268000
B9: 2 | C9: POWER UNIT | G9: DC37.5V(이즈파워) | M9: EA | N9: 1 | O9: 1000000 | S9: =N9*O9 -> 1000000
B10: 3 | C10: FRAME BOX | G10: ASS'Y(보성엔지니어) | M10: EA | N10: 1 | O10: 135000 | S10: =N10*O10 -> 135000
B11: 4 | C11: CONNECTOR | G11: Glenair ASS'Y(넥서스) | M11: EA | N11: 1 | O11: 87128 | S11: =N11*O11 -> 87128
B12: 5 | C12: LCD | G12: ASS'Y(i-Tech) | M12: EA | N12: 1 | O12: 13500 | S12: =N12*O12 -> 13500
B13: 6 | C13: TOUCH SCREEN | G13: ASS'Y(은강반도체) | M13: EA | N13: 1 | O13: 94500 | S13: =N13*O13 -> 94500
B14: 7 | C14: MAX1480ECEP | G14: ASS'Y(위니프로) | M14: EA | N14: 1 | O14: 33750 | S14: =N14*O14 -> 33750
B15: 8 | C15: Windows CE 라이센스 | G15: ASS'Y(i-Tech) | M15: EA | N15: 1 | O15: 22950 | S15: =N15*O15 -> 22950
B16: 9 | C16: 부자재 | G16: 기타 Connector 및 전선(은강 반도체) | M16: EA | N16: 1 | O16: 130000 | S16: =N16*O16 -> 130000
B17: 10
B18: 11
B19: 12
B20: 13
B21: 14
B22: 15
B23: 16
B24: 17
B25: 18
B26: 19
B27: 20
Q28: =SUM(Q8:R27) -> 0 | S28: =SUM(S8:T27) -> 3784828 | U28: =SUM(U8:V27) -> 0
A29: 원 가 항 목 | G29: 견 적 가 | J29: 조 사 가 | M29: 종 합 조 립 가 공 비 명 세 | N29: 공 정 명 | Q29: 조립시간 (HR) | S29: 가동임율 (￦/HR) | U29: 조립 가공비 | W29: 조립시간 (HR) | Y29: 가동임율 (￦/HR) | AA29: 조립 가공비
A30: 1 | C30: 자 작 | G30: =Q28 -> 0
A31: 2 | C31: 외 주 | G31: =S28+S87 -> 3784828 | N31: 기기조립 | Q31: 8 | S31: 24000 | U31: =S31*Q31 -> 192000
A32: 3 | C32: 수 입 | G32: =U28 -> 0 | N32: 기기배선 | Q32: 12 | S32: 24000 | U32: =S32*Q32 -> 288000
A33: 4 | C33: 재 료 비 | G33: =(G30+G31+G32) -> 3784828 | N33: 검 사 | Q33: 5 | S33: 24000 | U33: =S33*Q33 -> 120000
A34: 5 | C34: 노 무 비 | G34: =U38 -> 600000
A35: 6 | C35: 경 비 | G35: =G34*0.1 -> 60000
A36: 7 | C36: 가공비 | G36: =G34+G35 -> 660000
A37: 8 | B37: 제조원가 | G37: =G33+G36 -> 4444828
A38: 9 | B38: 재료관리비 | G38: =((G30*0.01)+(G31*0.01)+(G32*0.02)) -> 37848.28 | U38: =SUM(U31:V37) -> 600000
A39: 10 | B39: 판매 / 관리비 | G39: =G36*0.15 -> 99000 | M39: 특기사항
A40: 11 | B40: 이 윤 | G40: =(G36+G39)*0.15 -> 113850
A41: 12 | B41: 운반비 / PLT | G41: 0
...

Sheet AAR
A1: PROJ. 명 | C1: =총합계!C1 -> 덴버전동차 50량 | J1: 원가견적/조사서(갑) - ASSY 用 - | T1: 회 사 명 (코드) | X1: 주) 우 진 산 전
A2: 차 종 | T2: =총합계!T2 -> 2011 년 4 월 11 일
A3: 품 번 | J3: 수 량 | N3: 50 | T3: 결 재 | U3: 담 당 | W3: 과장 | Y3: 팀장 | AA3: 임원
A5: 품 명 | C5: AAR | J5: 도 면 NO
A6: 구 성 부 품 비 명 세 | B6: NO | C6: 부 번 | G6: 부 품 명 | M6: 단 위 | N6: 수 량 | O6: 단 가 | Q6: 견 적 가 | W6: 조사가
Q7: 자작 | S7: 외주 | U7: 수입 | W7: 자작 | Y7: 외주 | AA7: 수입
B8: 1 | C8: CPU BOARD | G8: AAB-1(RF-COM) | M8: EA | N8: 1 | O8: =599400*1.5 -> 899100 | S8: =N8*O8 -> 899100
B9: 2 | G9: AAB-1(RF-COM) | M9: EA | N9: 1 | O9: =414450*1.5 -> 621675 | S9: =N9*O9 -> 621675
B10: 3 | G10: BPB(RF-COM) | M10: EA | N10: 1 | O10: =202500*1.5 -> 303750 | S10: =N10*O10 -> 303750
B11: 4 | G11: SCB(RF-COM) | M11: EA | N11: 1 | O11: =337500*1.5 -> 506250 | S11: =N11*O11 -> 506250
B12: 5 | C12: POWER UNIT | G12: DC37.5V(이즈파워) | M12: EA | N12: 1 | O12: 2700000 | S12: =N12*O12 -> 2700000
B13: 6 | C13: FRAME BOX | G13: ASS'Y(보성엔지니어) | M13: EA | N13: 1 | O13: 344250 | S13: =N13*O13 -> 344250
B14: 7 | C14: CONNECTOR | G14: AMP(엠비콘넥터) | M14: EA | N14: 2 | O14: 87128 | S14: =N14*O14 -> 174256
B15: 8 | G15: Glenair ASS'Y(넥서스) | M15: EA | N15: 1 | O15: 31467 | S15: =N15*O15 -> 31467
B16: 9 | C16: MAX1480ECEPI | G16: ASS'Y(위니프로) | M16: EA | N16: 1 | O16: 33750 | S16: =N16*O16 -> 33750
B17: 10 | C17: 부자재 | G17: 기타 Connector 및 전선(은강반도체) | N17: 1 | O17: 130000 | S17: =N17*O17 -> 130000
B18: 11
B19: 12
B20: 13
B21: 14
B22: 15
B23: 16
B24: 17
B25: 18
B26: 19
B27: 20
Q28: =SUM(Q8:R27) -> 0 | S28: =SUM(S8:T27) -> 5744498 | U28: =SUM(U8:V27) -> 0
A29: 원 가 항 목 | G29: 견 적 가 | J29: 조 사 가 | M29: 종 합 조 립 가 공 비 명 세 | N29: 공 정 명 | Q29: 조립시간 (HR) | S29: 가동임율 (￦/HR) | U29: 조립 가공비 | W29: 조립시간 (HR) | Y29: 가동임율 (￦/HR) | AA29: 조립 가공비
A30: 1 | C30: 자 작 | G30: =Q28 -> 0
A31: 2 | C31: 외 주 | G31: =S28+S87 -> 5744498 | N31: 기기조립 | Q31: 8 | S31: 24000 | U31: =S31*Q31 -> 192000
A32: 3 | C32: 수 입 | G32: =U28 -> 0 | N32: 기기배선 | Q32: 13 | S32: 24000 | U32: =S32*Q32 -> 312000
A33: 4 | C33: 재 료 비 | G33: =(G30+G31+G32) -> 5744498 | N33: 검 사 | Q33: 6 | S33: 24000 | U33: =S33*Q33 -> 144000
A34: 5 | C34: 노 무 비 | G34: =U38 -> 648000
A35: 6 | C35: 경 비 | G35: =G34*0.1 -> 64800
A36: 7 | C36: 가공비 | G36: =G34+G35 -> 712800
A37: 8 | B37: 제조원가 | G37: =G33+G36 -> 6457298
A38: 9 | B38: 재료관리비 | G38: =((G30*0.01)+(G31*0.01)+(G32*0.02)) -> 57444.98 | U38: =SUM(U31:V37) -> 648000
A39: 10 | B39: 판매 / 관리비 | G39: =G36*0.15 -> 106920 | M39: 특기사항
A40: 11 | B40: 이 윤 | G40: =(G36+G39)*0.15 -> 122958
A41: 12 | B41: 운반비 / PLT | G41: 0
...

Sheet DPO
A1: PROJ. 명 | C1: =총합계!C1 -> 덴버전동차 50량 | J1: 원가견적/조사서(갑) - ASSY 用 - | T1: 회 사 명 (코드) | X1: 주) 우 진 산 전
A2: 차 종 | T2: =총합계!T2 -> 2011 년 4 월 11 일
A3: 품 번 | J3: 수 량 | N3: 50 | T3: 결 재 | U3: 담 당 | W3: 과장 | Y3: 팀장 | AA3: 임원
A5: 품 명 | C5: DPO | J5: 도 면 NO
A6: 구 성 부 품 비 명 세 | B6: NO | C6: 부 번 | G6: 부 품 명 | M6: 단 위 | N6: 수 량 | O6: 단 가 | Q6: 견 적 가 | W6: 조사가
Q7: 자작 | S7: 외주 | U7: 수입 | W7: 자작 | Y7: 외주 | AA7: 수입 | AD7: * VOIP 라이센스 비용 일부 분산.
B8: 1 | C8: CPU BOARD | G8: ASS'Y(RF_COM) | M8: EA | N8: 1 | O8: =1116450*1.3 -> 1451385 | S8: =N8*O8 -> 1451385 | AD8: * DualTone 기능을 분리 하는 과정에서 PCB 가격 상승.
B9: 2 | C9: POWER UNIT | G9: DC37.5V/5V(이즈파워) | M9: EA | N9: 1 | O9: 1000000 | S9: =N9*O9 -> 1000000 | AD9: * Glenair 컨넥터 가격 상승 및 Type 변경(ITS -> ITH)
B10: 3 | C10: FRAME BOX | G10: ASS'Y(보성엔지니어) | M10: EA | N10: 1 | O10: 189000 | S10: =N10*O10 -> 189000 | AD10: * SEPTA "DMJ" 를 DPO에 통합. (DMJ 가격이 추가)
B11: 4 | C11: CONNECTOR | G11: Glenair ASS'Y(넥서스) | M11: EA | N11: 1 | O11: 197627 | S11: =N11*O11 -> 197627 | AD11: * Power Module 가격 상승.
B12: 5 | C12: MICROPHONE | G12: ASS'Y(은강반도체) | M12: EA | N12: 1 | O12: 21735 | S12: =N12*O12 -> 21735 | AD12: * 가타 부수적인 컨넥터 가격 상승.
B13: 6 | C13: SPEAKER | G13: ASS'Y(삼미스피커) | M13: EA | N13: 1 | O13: 24003 | S13: =N13*O13 -> 24003 | AD13: * Switch 가격 상승.
B14: 7 | C14: SWITCH | G14: ASS'Y(이즈파워) | M14: EA | N14: 6 | O14: =102600*1.2 -> 123120 | S14: =N14*O14 -> 738720
B15: 8 | C15: PHONE JACK | G15: ASS'Y(은강반도체) | M15: EA | N15: 1 | O15: 1350 | S15: =N15*O15 -> 1350
B16: 9 | C16: 부자재 | G16: 기타 Connector 및 전선(은강반도체) | M16: EA | N16: 1 | O16: 120000 | S16: =N16*O16 -> 120000
B17: 10
B18: 11
B19: 12
B20: 13
B21: 14
B22: 15
B23: 16
B24: 17
B25: 18
B26: 19
B27: 20
Q28: =SUM(Q8:R27) -> 0 | S28: =SUM(S8:T27) -> 3743820 | U28: =SUM(U8:V27) -> 0
A29: 원 가 항 목 | G29: 견 적 가 | J29: 조 사 가 | M29: 종 합 조 립 가 공 비 명 세 | N29: 공 정 명 | Q29: 조립시간 (HR) | S29: 가동임율 (￦/HR) | U29: 조립 가공비 | W29: 조립시간 (HR) | Y29: 가동임율 (￦/HR) | AA29: 조립 가공비
A30: 1 | C30: 자 작 | G30: =Q28 -> 0
A31: 2 | C31: 외 주 | G31: =S28+S87 -> 3743820 | N31: 기기조립 | Q31: 6 | S31: 24000 | U31: =S31*Q31 -> 144000
A32: 3 | C32: 수 입 | G32: =U28 -> 0 | N32: 기기배선 | Q32: 12 | S32: 24000 | U32: =S32*Q32 -> 288000
A33: 4 | C33: 재 료 비 | G33: =(G30+G31+G32) -> 3743820 | N33: 검 사 | Q33: 6 | S33: 24000 | U33: =S33*Q33 -> 144000
A34: 5 | C34: 노 무 비 | G34: =U38 -> 576000
A35: 6 | C35: 경 비 | G35: =G34*0.1 -> 57600
A36: 7 | C36: 가공비 | G36: =G34+G35 -> 633600
A37: 8 | B37: 제조원가 | G37: =G33+G36 -> 4377420
A38: 9 | B38: 재료관리비 | G38: =((G30*0.01)+(G31*0.01)+(G32*0.02)) -> 37438.2 | U38: =SUM(U31:V37) -> 576000
A39: 10 | B39: 판매 / 관리비 | G39: =G36*0.15 -> 95040 | M39: 특기사항
A40: 11 | B40: 이 윤 | G40: =(G36+G39)*0.15 -> 109296
A41: 12 | B41: 운반비 / PLT | G41: 0
...

Sheet DMA
A1: PROJ. 명 | C1: =총합계!C1 -> 덴버전동차 50량 | J1: 원가견적/조사서(갑) - ASSY 用 - | T1: 회 사 명 (코드) | X1: 주) 우 진 산 전
A2: 차 종 | T2: =총합계!T2 -> 2011 년 4 월 11 일
A3: 품 번 | J3: 수 량 | N3: 50 | T3: 결 재 | U3: 담 당 | W3: 과장 | Y3: 팀장 | AA3: 임원
A5: 품 명 | C5: DMA | J5: 도 면 NO
A6: 구 성 부 품 비 명 세 | B6: NO | C6: 부 번 | G6: 부 품 명 | M6: 단 위 | N6: 수 량 | O6: 단 가 | Q6: 견 적 가 | W6: 조사가 | AD6: * ASS'Y 제품을 그대로 사용 하는 부분 이므로 "노무비" 없어도 될것 같습니다.
Q7: 자작 | S7: 외주 | U7: 수입 | W7: 자작 | Y7: 외주 | AA7: 수입 | AD7: * 노무비가 너무 높게 되어 있습니다.
B8: 1 | C8: MICROPHONE | G8: ASS'Y(은강반도체) | M8: EA | N8: 1 | O8: 410000 | S8: =N8*O8 -> 410000 | AC8: =ROUND(O8*1.1,-2) -> 451000
B9: 2 | S9: =N9*O9 -> 0 | AC9: =ROUND(O9*1.1,-2) -> 0
B10: 3 | S10: =N10*O10 -> 0 | AC10: =ROUND(O10*1.1,-2) -> 0
B11: 4 | S11: =N11*O11 -> 0 | AC11: =ROUND(O11*1.1,-2) -> 0
B12: 5 | AC12: =ROUND(O12*1.1,-2) -> 0
B13: 6 | AC13: =ROUND(O13*1.1,-2) -> 0
B14: 7 | AC14: =ROUND(O14*1.1,-2) -> 0
B15: 8 | AC15: =ROUND(O15*1.1,-2) -> 0
B16: 9 | AC16: =ROUND(O16*1.1,-2) -> 0
B17: 10 | AC17: =ROUND(O17*1.1,-2) -> 0
B18: 11 | AC18: =ROUND(O18*1.1,-2) -> 0
B19: 12 | AC19: =ROUND(O19*1.1,-2) -> 0
B20: 13 | AC20: =ROUND(O20*1.1,-2) -> 0
B21: 14 | AC21: =ROUND(O21*1.1,-2) -> 0
B22: 15 | AC22: =ROUND(O22*1.1,-2) -> 0
B23: 16 | AC23: =ROUND(O23*1.1,-2) -> 0
B24: 17 | AC24: =ROUND(O24*1.1,-2) -> 0
B25: 18
B26: 19
B27: 20
Q28: =SUM(Q8:R27) -> 0 | S28: =SUM(S8:T27) -> 410000 | U28: =SUM(U8:V27) -> 0
A29: 원 가 항 목 | G29: 견 적 가 | J29: 조 사 가 | M29: 종 합 조 립 가 공 비 명 세 | N29: 공 정 명 | Q29: 조립시간 (HR) | S29: 가동임율 (￦/HR) | U29: 조립 가공비 | W29: 조립시간 (HR) | Y29: 가동임율 (￦/HR) | AA29: 조립 가공비
A30: 1 | C30: 자 작 | G30: =Q28 -> 0
A31: 2 | C31: 외 주 | G31: =S28+S87 -> 410000 | N31: 기기조립 | Q31: 4 | S31: 24000 | U31: =S31*Q31 -> 96000
A32: 3 | C32: 수 입 | G32: =U28 -> 0 | N32: 검 사 | Q32: 4 | S32: 24000 | U32: =S32*Q32 -> 96000
A33: 4 | C33: 재 료 비 | G33: =(G30+G31+G32) -> 410000
A34: 5 | C34: 노 무 비 | G34: =U38 -> 192000
A35: 6 | C35: 경 비 | G35: =G34*0.1 -> 19200
A36: 7 | C36: 가공비 | G36: =G34+G35 -> 211200
A37: 8 | B37: 제조원가 | G37: =G33+G36 -> 621200
A38: 9 | B38: 재료관리비 | G38: =((G30*0.01)+(G31*0.01)+(G32*0.02)) -> 4100 | U38: =SUM(U31:V37) -> 192000
A39: 10 | B39: 판매 / 관리비 | G39: =G36*0.15 -> 31680 | M39: 특기사항
A40: 11 | B40: 이 윤 | G40: =(G36+G39)*0.15 -> 36432
A41: 12 | B41: 운반비 / PLT | G41: 0
...

Sheet CSP
A1: PROJ. 명 | C1: =총합계!C1 -> 덴버전동차 50량 | J1: 원가견적/조사서(갑) - ASSY 用 - | T1: 회 사 명 (코드) | X1: 주) 우 진 산 전
A2: 차 종 | T2: =총합계!T2 -> 2011 년 4 월 11 일
A3: 품 번 | J3: 수 량 | N3: 50 | T3: 결 재 | U3: 담 당 | W3: 과장 | Y3: 팀장 | AA3: 임원
A5: 품 명 | C5: CSP | J5: 도 면 NO
A6: 구 성 부 품 비 명 세 | B6: NO | C6: 부 번 | G6: 부 품 명 | M6: 단 위 | N6: 수 량 | O6: 단 가 | Q6: 견 적 가 | W6: 조사가 | AD6: * 방수 부분 보완을 위해 스피커 사양 변경.
Q7: 자작 | S7: 외주 | U7: 수입 | W7: 자작 | Y7: 외주 | AA7: 수입 | AD7: * Volume Control 수입 품 수량 제한으로 대량 구입.
B8: 1 | C8: FRAME BOX | G8: ASS'Y(보성엔지니어) | M8: EA | N8: 1 | O8: 110000 | S8: =N8*O8 -> 110000 | AC8: =ROUND(O8*1.1,-2) -> 121000
B9: 2 | C9: 부자재 | G9: 기타 Conncector 및 전선(은강반도체) | M9: EA | N9: 1 | O9: 80000 | S9: =N9*O9 -> 80000 | AC9: =ROUND(O9*1.1,-2) -> 88000
B10: 3 | C10: SPEAKER | G10: SPEAKER(삼미) | M10: EA | N10: 1 | O10: =21600*1.15 -> 24840 | S10: =N10*O10 -> 24840 | AC10: =ROUND(O10*1.1,-2) -> 27300
B11: 4 | C11: KNOB | G11: KNOB(은강반도체) | M11: EA | N11: 1 | O11: 17550 | S11: =N11*O11 -> 17550 | AC11: =ROUND(O11*1.1,-2) -> 19300
B12: 5 | C12: VOLUME CONTROL | G12: VOLUME CONTROL(DuraCap International Inc) | M12: EA | N12: 1 | O12: 5400 | S12: =N12*O12 -> 5400 | AC12: =ROUND(O12*1.1,-2) -> 5900
B13: 6 | AC13: =ROUND(O13*1.1,-2) -> 0
B14: 7 | AC14: =ROUND(O14*1.1,-2) -> 0
B15: 8
B16: 9
B17: 10
B18: 11
B19: 12
B20: 13
B21: 14
B22: 15
B23: 16
B24: 17
B25: 18
B26: 19
B27: 20
Q28: =SUM(Q8:R27) -> 0 | S28: =SUM(S8:T27) -> 237790 | U28: =SUM(U8:V27) -> 0
A29: 원 가 항 목 | G29: 견 적 가 | J29: 조 사 가 | M29: 종 합 조 립 가 공 비 명 세 | N29: 공 정 명 | Q29: 조립시간 (HR) | S29: 가동임율 (￦/HR) | U29: 조립 가공비 | W29: 조립시간 (HR) | Y29: 가동임율 (￦/HR) | AA29: 조립 가공비
A30: 1 | C30: 자 작 | G30: =Q28 -> 0
A31: 2 | C31: 외 주 | G31: =S28+S87 -> 237790 | N31: 기기조립 | Q31: 1 | S31: 24000 | U31: =S31*Q31 -> 24000
A32: 3 | C32: 수 입 | G32: =U28 -> 0 | N32: 기기배선 | Q32: 1 | S32: 24000 | U32: =S32*Q32 -> 24000
A33: 4 | C33: 재 료 비 | G33: =(G30+G31+G32) -> 237790 | N33: 검 사 | Q33: 1 | S33: 24000 | U33: =S33*Q33 -> 24000
A34: 5 | C34: 노 무 비 | G34: =U38 -> 72000
A35: 6 | C35: 경 비 | G35: =G34*0.1 -> 7200
A36: 7 | C36: 가공비 | G36: =G34+G35 -> 79200
A37: 8 | B37: 제조원가 | G37: =G33+G36 -> 316990
A38: 9 | B38: 재료관리비 | G38: =((G30*0.01)+(G31*0.01)+(G32*0.02)) -> 2377.9 | U38: =SUM(U31:V37) -> 72000
A39: 10 | B39: 판매 / 관리비 | G39: =G36*0.15 -> 11880 | M39: 특기사항
A40: 11 | B40: 이 윤 | G40: =(G36+G39)*0.15 -> 13662
A41: 12 | B41: 운반비 / PLT | G41: 0
...

Sheet CPO
A1: PROJ. 명 | C1: =총합계!C1 -> 덴버전동차 50량 | J1: 원가견적/조사서(갑) - ASSY 用 - | T1: 회 사 명 (코드) | X1: 주) 우 진 산 전
A2: 차 종 | T2: =총합계!T2 -> 2011 년 4 월 11 일
A3: 품 번 | J3: 수 량 | N3: 50 | T3: 결 재 | U3: 담 당 | W3: 과장 | Y3: 팀장 | AA3: 임원
A5: 품 명 | C5: CPO | J5: 도 면 NO
A6: 구 성 부 품 비 명 세 | B6: NO | C6: 부 번 | G6: 부 품 명 | M6: 단 위 | N6: 수 량 | O6: 단 가 | Q6: 견 적 가 | W6: 조사가 | AD6: * VOIP 라이센스 비용 일부 분산.
Q7: 자작 | S7: 외주 | U7: 수입 | W7: 자작 | Y7: 외주 | AA7: 수입 | AD7: * DualTone 기능을 분리 하는 과정에서 PCB 가격 상승.
B8: 1 | C8: CPU BOARD | G8: ASS'Y(RF-COM) | M8: EA | N8: 1 | O8: 1530000 | S8: =N8*O8 -> 1530000 | AC8: =ROUND(O8*1.1,-2) -> 1683000 | AD8: * Power Module 가격 상승.
B9: 2 | C9: POWER UNIT | G9: DC37.5V/5V(이즈파워) | M9: EA | N9: 1 | O9: 1000000 | S9: =N9*O9 -> 1000000 | AC9: =ROUND(O9*1.1,-2) -> 1100000 | AD9: * Switch 가격 상승.
B10: 3 | C10: FRAME BOX | G10: ASS'Y(보성엔지니어) | M10: EA | N10: 1 | O10: 189000 | S10: =N10*O10 -> 189000 | AC10: =ROUND(O10*1.1,-2) -> 207900 | AD10: * Glenair 컨넥터 가격 상승 및 Type 변경(ITS -> ITH)
B11: 4 | C11: CONNECTOR | G11: Glenair ASS'Y(넥서스) | M11: EA | N11: 1 | O11: 131435 | S11: =N11*O11 -> 131435 | AC11: =ROUND(O11*1.1,-2) -> 144600
B12: 5 | C12: MICROPHONE | G12: ASS'Y(은강반도체) | M12: EA | N12: 1 | O12: 21735 | S12: =N12*O12 -> 21735 | AC12: =ROUND(O12*1.1,-2) -> 23900
B13: 6 | C13: SPEAKER | G13: ASS'Y(삼미) | M13: EA | N13: 1 | O13: 24003 | S13: =N13*O13 -> 24003 | AC13: =ROUND(O13*1.1,-2) -> 26400
B14: 7 | C14: SWITCH | G14: ASS'Y(이즈파워) | M14: EA | N14: 6 | O14: 102600 | S14: =N14*O14 -> 615600 | AC14: =ROUND(O14*1.1,-2) -> 112900
B15: 8 | C15: 부자재 | G15: 기타 Connector 및 전선(은강반도체) | M15: EA | N15: 1 | O15: 110000 | S15: =N15*O15 -> 110000 | AC15: =ROUND(O15*1.1,-2) -> 121000
B16: 9 | AC16: =ROUND(O16*1.1,-2) -> 0
B17: 10 | AC17: =ROUND(O17*1.1,-2) -> 0
B18: 11 | AC18: =ROUND(O18*1.1,-2) -> 0
B19: 12 | AC19: =ROUND(O19*1.1,-2) -> 0
B20: 13 | AC20: =ROUND(O20*1.1,-2) -> 0
B21: 14 | AC21: =ROUND(O21*1.1,-2) -> 0
B22: 15 | AC22: =ROUND(O22*1.1,-2) -> 0
B23: 16 | AC23: =ROUND(O23*1.1,-2) -> 0
B24: 17 | AC24: =ROUND(O24*1.1,-2) -> 0
B25: 18 | AC25: =ROUND(O25*1.1,-2) -> 0
B26: 19 | AC26: =ROUND(O26*1.1,-2) -> 0
B27: 20 | AC27: =ROUND(O27*1.1,-2) -> 0
Q28: =SUM(Q8:R27) -> 0 | S28: =SUM(S8:T27) -> 3621773 | U28: =SUM(U8:V27) -> 0 | AC28: =ROUND(O28*1.1,-2) -> 0
A29: 원 가 항 목 | G29: 견 적 가 | J29: 조 사 가 | M29: 종 합 조 립 가 공 비 명 세 | N29: 공 정 명 | Q29: 조립시간 (HR) | S29: 가동임율 (￦/HR) | U29: 조립 가공비 | W29: 조립시간 (HR) | Y29: 가동임율 (￦/HR) | AA29: 조립 가공비 | AC29: =ROUND(O29*1.1,-2) -> 0
A30: 1 | C30: 자 작 | G30: =Q28 -> 0 | AC30: =ROUND(O30*1.1,-2) -> 0
A31: 2 | C31: 외 주 | G31: =S28+S87 -> 3621773 | N31: 기기조립 | Q31: 7 | S31: 24000 | U31: =S31*Q31 -> 168000 | AC31: =ROUND(O31*1.1,-2) -> 0
A32: 3 | C32: 수 입 | G32: =U28 -> 0 | N32: 기기배선 | Q32: 10 | S32: 24000 | U32: =S32*Q32 -> 240000 | AC32: =ROUND(O32*1.1,-2) -> 0
A33: 4 | C33: 재 료 비 | G33: =(G30+G31+G32) -> 3621773 | N33: 검 사 | Q33: 4 | S33: 24000 | U33: =S33*Q33 -> 96000 | AC33: =ROUND(O33*1.1,-2) -> 0
A34: 5 | C34: 노 무 비 | G34: =U38 -> 504000 | AC34: =ROUND(O34*1.1,-2) -> 0
A35: 6 | C35: 경 비 | G35: =G34*0.1 -> 50400 | AC35: =ROUND(O35*1.1,-2) -> 0
A36: 7 | C36: 가공비 | G36: =G34+G35 -> 554400 | AC36: =ROUND(O36*1.1,-2) -> 0
A37: 8 | B37: 제조원가 | G37: =G33+G36 -> 4176173 | AC37: =ROUND(O37*1.1,-2) -> 0
A38: 9 | B38: 재료관리비 | G38: =((G30*0.01)+(G31*0.01)+(G32*0.02)) -> 36217.73 | U38: =SUM(U31:V37) -> 504000 | AC38: =ROUND(O38*1.1,-2) -> 0
A39: 10 | B39: 판매 / 관리비 | G39: =G36*0.15 -> 83160 | M39: 특기사항 | AC39: =ROUND(O39*1.1,-2) -> 0
A40: 11 | B40: 이 윤 | G40: =(G36+G39)*0.15 -> 95634 | AC40: =ROUND(O40*1.1,-2) -> 0
A41: 12 | B41: 운반비 / PLT | G41: 0 | AC41: =ROUND(O41*1.1,-2) -> 0
...

Sheet PEI
A1: PROJ. 명 | C1: =총합계!C1 -> 덴버전동차 50량 | J1: 원가견적/조사서(갑) - ASSY 用 - | T1: 회 사 명 (코드) | X1: 주) 우 진 산 전
A2: 차 종 | T2: =CPO!T2 -> 2011 년 4 월 11 일
A3: 품 번 | J3: 수 량 | N3: 50 | T3: 결 재 | U3: 담 당 | W3: 과장 | Y3: 팀장 | AA3: 임원
A5: 품 명 | C5: PEI | J5: 도 면 NO
A6: 구 성 부 품 비 명 세 | B6: NO | C6: 부 번 | G6: 부 품 명 | M6: 단 위 | N6: 수 량 | O6: 단 가 | Q6: 견 적 가 | W6: 조사가
Q7: 자작 | S7: 외주 | U7: 수입 | W7: 자작 | Y7: 외주 | AA7: 수입
B8: 1 | C8: CPU BOARD | G8: ASS'Y(RF-COM) | M8: EA | N8: 1 | O8: 1397250 | S8: =N8*O8 -> 1397250
B9: 2 | C9: POWER UNIT | G9: DC37.5V/5V(이즈파워) | M9: EA | N9: 1 | O9: 1000000 | S9: =N9*O9 -> 1000000
B10: 3 | C10: FRAME BOX | G10: ASS'Y(보성엔지니어) | M10: EA | N10: 1 | O10: 216000 | S10: =N10*O10 -> 216000
B11: 4 | C11: CONNECTOR | G11: Glenair ASS'Y(넥서스) | M11: EA | N11: 1 | O11: 269657 | S11: =N11*O11 -> 269657
B12: 5 | C12: MICROPHONE | G12: ASS'Y(은강반도체) | M12: EA | N12: 1 | O12: 21735 | S12: =N12*O12 -> 21735
B13: 6 | C13: SPEAKER | G13: ASS'Y(삼미) | M13: EA | N13: 1 | O13: 24003 | S13: =N13*O13 -> 24003
B14: 7 | C14: SWITCH | G14: ASS'Y(이즈파워) | M14: EA | N14: 1 | O14: 155250 | S14: =N14*O14 -> 155250
B15: 8 | C15: 부자재 | G15: 기타 Connector 및 전선(은강반도체) | M15: EA | N15: 1 | O15: 67500 | S15: =N15*O15 -> 67500
B16: 9
B17: 10
B18: 11
B19: 12
B20: 13
B21: 14
B22: 15
B23: 16
B24: 17
B25: 18
B26: 19
B27: 20
Q28: =SUM(Q8:R27) -> 0 | S28: =SUM(S8:T27) -> 3151395 | U28: =SUM(U8:V27) -> 0
A29: 원 가 항 목 | G29: 견 적 가 | J29: 조 사 가 | M29: 종 합 조 립 가 공 비 명 세 | N29: 공 정 명 | Q29: 조립시간 (HR) | S29: 가동임율 (￦/HR) | U29: 조립 가공비 | W29: 조립시간 (HR) | Y29: 가동임율 (￦/HR) | AA29: 조립 가공비
A30: 1 | C30: 자 작 | G30: =Q28 -> 0
A31: 2 | C31: 외 주 | G31: =S28+S87 -> 3151395 | N31: 기기조립 | Q31: 4 | S31: 24000 | U31: =S31*Q31 -> 96000
A32: 3 | C32: 수 입 | G32: =U28 -> 0 | N32: 기기배선 | Q32: 6 | S32: 24000 | U32: =S32*Q32 -> 144000
A33: 4 | C33: 재 료 비 | G33: =(G30+G31+G32) -> 3151395 | N33: 검 사 | Q33: 2 | S33: 24000 | U33: =S33*Q33 -> 48000
A34: 5 | C34: 노 무 비 | G34: =U38 -> 288000
A35: 6 | C35: 경 비 | G35: =G34*0.1 -> 28800
A36: 7 | C36: 가공비 | G36: =G34+G35 -> 316800
A37: 8 | B37: 제조원가 | G37: =G33+G36 -> 3468195
A38: 9 | B38: 재료관리비 | G38: =((G30*0.01)+(G31*0.01)+(G32*0.02)) -> 31513.95 | U38: =SUM(U31:V33) -> 288000
A39: 10 | B39: 판매 / 관리비 | G39: =G36*0.15 -> 47520 | M39: 특기사항
A40: 11 | B40: 이 윤 | G40: =(G36+G39)*0.15 -> 54648
A41: 12 | B41: 운반비 / PLT | G41: 0
...

Sheet ISP
A1: PROJ. 명 | C1: =총합계!C1 -> 덴버전동차 50량 | J1: 원가견적/조사서(갑) - ASSY 用 - | T1: 회 사 명 (코드) | X1: 주) 우 진 산 전
A2: 차 종 | T2: =총합계!T2 -> 2011 년 4 월 11 일
A3: 품 번 | J3: 수 량 | N3: 50 | T3: 결 재 | U3: 담 당 | W3: 과장 | Y3: 팀장 | AA3: 임원
A5: 품 명 | C5: ISP | J5: 도 면 NO
A6: 구 성 부 품 비 명 세 | B6: NO | C6: 부 번 | G6: 부 품 명 | M6: 단 위 | N6: 수 량 | O6: 단 가 | Q6: 견 적 가 | W6: 조사가 | AD6: * 방수 부분 보완을 위해 스피커 사양 변경.
Q7: 자작 | S7: 외주 | U7: 수입 | W7: 자작 | Y7: 외주 | AA7: 수입 | AD7: * TRANSFORME 가격 상승.
B8: 1 | C8: FRAME BOX | G8: ASS'Y(보성엔지니어) | M8: EA | N8: 1 | O8: 67500 | S8: =N8*O8 -> 67500 | AC8: =ROUND(O8*1.1,-2) -> 74300
B9: 2 | C9: CPU BOARD | G9: ASS'Y(ANTS) | M9: EA | N9: 1 | O9: 47250 | S9: =N9*O9 -> 47250 | AC9: =ROUND(O9*1.1,-2) -> 52000
B10: 3 | C10: TRANSFORME | G10: ASS'Y(삼익전자) | M10: EA | N10: 1 | O10: 26325 | S10: =N10*O10 -> 26325 | AC10: =ROUND(O10*1.1,-2) -> 29000
B11: 4 | C11: SPEAKER | G11: ASS'Y(삼미) | M11: EA | N11: 1 | O11: 21600 | S11: =N11*O11 -> 21600 | AC11: =ROUND(O11*1.1,-2) -> 23800
B12: 5 | C12: 부자재 | G12: 기타 Connector 및 전선(은강반도체) | M12: EA | N12: 1 | O12: 67500 | S12: =N12*O12 -> 67500 | AC12: =ROUND(O12*1.1,-2) -> 74300
B13: 6 | S13: =N13*O13 -> 0 | AC13: =ROUND(O13*1.1,-2) -> 0
B14: 7 | S14: =N14*O14 -> 0 | AC14: =ROUND(O14*1.1,-2) -> 0
B15: 8 | S15: =N15*O15 -> 0 | AC15: =ROUND(O15*1.1,-2) -> 0
B16: 9 | S16: =N16*O16 -> 0 | AC16: =ROUND(O16*1.1,-2) -> 0
B17: 10 | S17: =N17*O17 -> 0 | AC17: =ROUND(O17*1.1,-2) -> 0
B18: 11 | S18: =N18*O18 -> 0 | AC18: =ROUND(O18*1.1,-2) -> 0
B19: 12 | S19: =N19*O19 -> 0 | AC19: =ROUND(O19*1.1,-2) -> 0
B20: 13 | S20: =N20*O20 -> 0
B21: 14 | S21: =N21*O21 -> 0
B22: 15 | S22: =N22*O22 -> 0
B23: 16 | S23: =N23*O23 -> 0
B24: 17 | S24: =N24*O24 -> 0
B25: 18 | S25: =N25*O25 -> 0
B26: 19 | S26: =N26*O26 -> 0
B27: 20 | S27: =N27*O27 -> 0
Q28: =SUM(Q8:R27) -> 0 | S28: =SUM(S8:T27) -> 230175 | U28: =SUM(U8:V27) -> 0
A29: 원 가 항 목 | G29: 견 적 가 | J29: 조 사 가 | M29: 종 합 조 립 가 공 비 명 세 | N29: 공 정 명 | Q29: 조립시간 (HR) | S29: 가동임율 (￦/HR) | U29: 조립 가공비 | W29: 조립시간 (HR) | Y29: 가동임율 (￦/HR) | AA29: 조립 가공비
A30: 1 | C30: 자 작 | G30: =Q28 -> 0
A31: 2 | C31: 외 주 | G31: =S28+S87 -> 230175 | N31: 기기조립 | Q31: 1 | S31: 24000 | U31: =S31*Q31 -> 24000
A32: 3 | C32: 수 입 | G32: =U28 -> 0 | N32: 기기배선 | Q32: 1 | S32: 24000 | U32: =S32*Q32 -> 24000
A33: 4 | C33: 재 료 비 | G33: =(G30+G31+G32) -> 230175 | N33: 검 사 | Q33: 1 | S33: 24000 | U33: =S33*Q33 -> 24000
A34: 5 | C34: 노 무 비 | G34: =U38 -> 72000
A35: 6 | C35: 경 비 | G35: =G34*0.1 -> 7200
A36: 7 | C36: 가공비 | G36: =G34+G35 -> 79200
A37: 8 | B37: 제조원가 | G37: =G33+G36 -> 309375
A38: 9 | B38: 재료관리비 | G38: =((G30*0.01)+(G31*0.01)+(G32*0.02)) -> 2301.75 | U38: =SUM(U31:V37) -> 72000
A39: 10 | B39: 판매 / 관리비 | G39: =G36*0.15 -> 11880 | M39: 특기사항
A40: 11 | B40: 이 윤 | G40: =(G36+G39)*0.15 -> 13662
A41: 12 | B41: 운반비 / PLT | G41: 0
...

Sheet ESP
A1: PROJ. 명 | C1: =총합계!C1 -> 덴버전동차 50량 | J1: 원가견적/조사서(갑) - ASSY 用 - | T1: 회 사 명 (코드) | X1: 주) 우 진 산 전
A2: 차 종 | T2: =총합계!T2 -> 2011 년 4 월 11 일
A3: 품 번 | J3: 수 량 | N3: 50 | T3: 결 재 | U3: 담 당 | W3: 과장 | Y3: 팀장 | AA3: 임원
A5: 품 명 | C5: ESP | J5: 도 면 NO
A6: 구 성 부 품 비 명 세 | B6: NO | C6: 부 번 | G6: 부 품 명 | M6: 단 위 | N6: 수 량 | O6: 단 가 | Q6: 견 적 가 | W6: 조사가 | AD6: * 방수 부분 보완을 위해 스피커 사양 변경.
Q7: 자작 | S7: 외주 | U7: 수입 | W7: 자작 | Y7: 외주 | AA7: 수입
B8: 1 | C8: FRAME BOX | G8: ASS'Y(보성엔지니어) | M8: EA | N8: 1 | O8: 67500 | S8: =N8*O8 -> 67500 | AC8: =ROUND(O8*1.1,-2) -> 74300
B9: 2 | C9: CPU BOARD | G9: ASS'Y(ANTS) | M9: EA | N9: 1 | O9: 47250 | S9: =N9*O9 -> 47250 | AC9: =ROUND(O9*1.1,-2) -> 52000
B10: 3 | C10: SPEAKER | G10: ASS'Y(삼미스피커) | M10: EA | N10: 1 | O10: 21600 | S10: =N10*O10 -> 21600 | AC10: =ROUND(O10*1.1,-2) -> 23800
B11: 4 | C11: 부자재 | G11: 기타 Connector 및 전선(은강반도체) | M11: EA | N11: 1 | O11: 67500 | S11: =N11*O11 -> 67500 | AC11: =ROUND(O11*1.1,-2) -> 74300
B12: 5 | S12: =N12*O12 -> 0 | AC12: =ROUND(O12*1.1,-2) -> 0
B13: 6 | S13: =N13*O13 -> 0 | AC13: =ROUND(O13*1.1,-2) -> 0
B14: 7 | S14: =N14*O14 -> 0 | AC14: =ROUND(O14*1.1,-2) -> 0
B15: 8 | S15: =N15*O15 -> 0 | AC15: =ROUND(O15*1.1,-2) -> 0
B16: 9 | S16: =N16*O16 -> 0 | AC16: =ROUND(O16*1.1,-2) -> 0
B17: 10 | S17: =N17*O17 -> 0 | AC17: =ROUND(O17*1.1,-2) -> 0
B18: 11 | AC18: =ROUND(O18*1.1,-2) -> 0
B19: 12 | AC19: =ROUND(O19*1.1,-2) -> 0
B20: 13 | AC20: =ROUND(O20*1.1,-2) -> 0
B21: 14
B22: 15
B23: 16
B24: 17
B25: 18
B26: 19
B27: 20
Q28: =SUM(Q8:R27) -> 0 | S28: =SUM(S8:T27) -> 203850 | U28: =SUM(U8:V27) -> 0
A29: 원 가 항 목 | G29: 견 적 가 | J29: 조 사 가 | M29: 종 합 조 립 가 공 비 명 세 | N29: 공 정 명 | Q29: 조립시간 (HR) | S29: 가동임율 (￦/HR) | U29: 조립 가공비 | W29: 조립시간 (HR) | Y29: 가동임율 (￦/HR) | AA29: 조립 가공비
A30: 1 | C30: 자 작 | G30: =Q28 -> 0
A31: 2 | C31: 외 주 | G31: =S28+S87 -> 203850 | N31: 기기조립 | Q31: 1 | S31: 24000 | U31: =S31*Q31 -> 24000
A32: 3 | C32: 수 입 | G32: =U28 -> 0 | N32: 기기배선 | Q32: 1 | S32: 24000 | U32: =S32*Q32 -> 24000
A33: 4 | C33: 재 료 비 | G33: =(G30+G31+G32) -> 203850 | N33: 검 사 | Q33: 1 | S33: 24000 | U33: =S33*Q33 -> 24000
A34: 5 | C34: 노 무 비 | G34: =U38 -> 72000
A35: 6 | C35: 경 비 | G35: =G34*0.1 -> 7200
A36: 7 | C36: 가공비 | G36: =G34+G35 -> 79200
A37: 8 | B37: 제조원가 | G37: =G33+G36 -> 283050
A38: 9 | B38: 재료관리비 | G38: =((G30*0.01)+(G31*0.01)+(G32*0.02)) -> 2038.5 | U38: =SUM(U31:V37) -> 72000
A39: 10 | B39: 판매 / 관리비 | G39: =G36*0.15 -> 11880 | M39: 특기사항
A40: 11 | B40: 이 윤 | G40: =(G36+G39)*0.15 -> 13662
A41: 12 | B41: 운반비 / PLT | G41: 0
...

Sheet TRF1
A1: PROJ. 명 | C1: =총합계!C1 -> 덴버전동차 50량 | J1: 원가견적/조사서(갑) - ASSY 用 - | T1: 회 사 명 (코드) | X1: 주) 우 진 산 전
A2: 차 종 | T2: =총합계!T2 -> 2011 년 4 월 11 일
A3: 품 번 | J3: 수 량 | N3: 50 | T3: 결 재 | U3: 담 당 | W3: 과장 | Y3: 팀장 | AA3: 임원
A5: 품 명 | C5: TRF1 | J5: 도 면 NO
A6: 구 성 부 품 비 명 세 | B6: NO | C6: 부 번 | G6: 부 품 명 | M6: 단 위 | N6: 수 량 | O6: 단 가 | Q6: 견 적 가 | W6: 조사가
Q7: 자작 | S7: 외주 | U7: 수입 | W7: 자작 | Y7: 외주 | AA7: 수입
B8: 1 | C8: FRAME BOX | G8: ASS'Y(보성엔지니어) | M8: EA | N8: 1 | O8: 14850 | S8: =N8*O8 -> 14850 | AC8: =ROUND(O8*1.1,-2) -> 16300
B9: 2 | C9: CPU BOARD | G9: ASS'Y(ANTS) | M9: EA | N9: 1 | O9: 47250 | S9: =N9*O9 -> 47250 | AC9: =ROUND(O9*1.1,-2) -> 52000
B10: 3 | C10: TRANSFORMS | G10: ASS'Y(삼익전자) | M10: EA | N10: 1 | O10: 26325 | S10: =N10*O10 -> 26325 | AC10: =ROUND(O10*1.1,-2) -> 29000
B11: 4 | C11: 부자재 | G11: 기타 Connector 및 전선(은강반도체) | M11: EA | N11: 1 | O11: 67500 | S11: =N11*O11 -> 67500 | AC11: =ROUND(O11*1.1,-2) -> 74300
B12: 5 | AC12: =ROUND(O12*1.1,-2) -> 0
B13: 6 | AC13: =ROUND(O13*1.1,-2) -> 0
B14: 7 | AC14: =ROUND(O14*1.1,-2) -> 0
B15: 8 | AC15: =ROUND(O15*1.1,-2) -> 0
B16: 9 | AC16: =ROUND(O16*1.1,-2) -> 0
B17: 10 | AC17: =ROUND(O17*1.1,-2) -> 0
B18: 11 | AC18: =ROUND(O18*1.1,-2) -> 0
B19: 12 | AC19: =ROUND(O19*1.1,-2) -> 0
B20: 13
B21: 14
B22: 15
B23: 16
B24: 17
B25: 18
B26: 19
B27: 20
Q28: =SUM(Q8:R27) -> 0 | S28: =SUM(S8:T27) -> 155925 | U28: =SUM(U8:V27) -> 0
A29: 원 가 항 목 | G29: 견 적 가 | J29: 조 사 가 | M29: 종 합 조 립 가 공 비 명 세 | N29: 공 정 명 | Q29: 조립시간 (HR) | S29: 가동임율 (￦/HR) | U29: 조립 가공비 | W29: 조립시간 (HR) | Y29: 가동임율 (￦/HR) | AA29: 조립 가공비
A30: 1 | C30: 자 작 | G30: =Q28 -> 0
A31: 2 | C31: 외 주 | G31: =S28+S87 -> 155925 | N31: 기기조립 | Q31: 1 | S31: 24000 | U31: =S31*Q31 -> 24000
A32: 3 | C32: 수 입 | G32: =U28 -> 0 | N32: 기기배선 | Q32: 1 | S32: 24000 | U32: =S32*Q32 -> 24000
A33: 4 | C33: 재 료 비 | G33: =(G30+G31+G32) -> 155925 | N33: 검 사 | Q33: 1 | S33: 24000 | U33: =S33*Q33 -> 24000
A34: 5 | C34: 노 무 비 | G34: =U38 -> 72000
A35: 6 | C35: 경 비 | G35: =G34*0.1 -> 7200
A36: 7 | C36: 가공비 | G36: =G34+G35 -> 79200
A37: 8 | B37: 제조원가 | G37: =G33+G36 -> 235125
A38: 9 | B38: 재료관리비 | G38: =((G30*0.01)+(G31*0.01)+(G32*0.02)) -> 1559.25 | U38: =SUM(U31:V37) -> 72000
A39: 10 | B39: 판매 / 관리비 | G39: =G36*0.15 -> 11880 | M39: 특기사항
A40: 11 | B40: 이 윤 | G40: =(G36+G39)*0.15 -> 13662
A41: 12 | B41: 운반비 / PLT | G41: 0
...

Sheet TRF2
A1: PROJ. 명 | C1: =총합계!C1 -> 덴버전동차 50량 | J1: 원가견적/조사서(갑) - ASSY 用 - | T1: 회 사 명 (코드) | X1: 주) 우 진 산 전
A2: 차 종 | T2: =총합계!T2 -> 2011 년 4 월 11 일
A3: 품 번 | J3: 수 량 | N3: 50 | T3: 결 재 | U3: 담 당 | W3: 과장 | Y3: 팀장 | AA3: 임원
A5: 품 명 | C5: TRF2 | J5: 도 면 NO
A6: 구 성 부 품 비 명 세 | B6: NO | C6: 부 번 | G6: 부 품 명 | M6: 단 위 | N6: 수 량 | O6: 단 가 | Q6: 견 적 가 | W6: 조사가
Q7: 자작 | S7: 외주 | U7: 수입 | W7: 자작 | Y7: 외주 | AA7: 수입
B8: 1 | C8: FRAME BOX | G8: ASS'Y(보성엔지니어) | M8: EA | N8: 1 | O8: 1350 | S8: =N8*O8 -> 1350 | AC8: =ROUND(O8*1.1,-2) -> 1500
B9: 2 | C9: CONNECTOR | G9: Glenair ASS'Y(넥서스) | M9: EA | N9: 1 | O9: 57444 | S9: =N9*O9 -> 57444 | AC9: =ROUND(O9*1.1,-2) -> 63200
B10: 3 | C10: 부자재 | G10: 기타 Connector 및 전선(은강반도체) | M10: EA | N10: 1 | O10: 27000 | S10: =N10*O10 -> 27000 | AC10: =ROUND(O10*1.1,-2) -> 29700
B11: 4 | S11: =N11*O11 -> 0 | AC11: =ROUND(O11*1.1,-2) -> 0
B12: 5 | AC12: =ROUND(O12*1.1,-2) -> 0
B13: 6 | AC13: =ROUND(O13*1.1,-2) -> 0
B14: 7 | AC14: =ROUND(O14*1.1,-2) -> 0
B15: 8 | AC15: =ROUND(O15*1.1,-2) -> 0
B16: 9 | AC16: =ROUND(O16*1.1,-2) -> 0
B17: 10 | AC17: =ROUND(O17*1.1,-2) -> 0
B18: 11 | AC18: =ROUND(O18*1.1,-2) -> 0
B19: 12 | AC19: =ROUND(O19*1.1,-2) -> 0
B20: 13
B21: 14
B22: 15
B23: 16
B24: 17
B25: 18
B26: 19
B27: 20
Q28: =SUM(Q8:R27) -> 0 | S28: =SUM(S8:T27) -> 85794 | U28: =SUM(U8:V27) -> 0
A29: 원 가 항 목 | G29: 견 적 가 | J29: 조 사 가 | M29: 종 합 조 립 가 공 비 명 세 | N29: 공 정 명 | Q29: 조립시간 (HR) | S29: 가동임율 (￦/HR) | U29: 조립 가공비 | W29: 조립시간 (HR) | Y29: 가동임율 (￦/HR) | AA29: 조립 가공비
A30: 1 | C30: 자 작 | G30: =Q28 -> 0
A31: 2 | C31: 외 주 | G31: =S28+S87 -> 85794 | N31: 기기조립 | Q31: 1 | S31: 24000 | U31: =S31*Q31 -> 24000
A32: 3 | C32: 수 입 | G32: =U28 -> 0 | N32: 기기배선 | Q32: 1 | S32: 24000 | U32: =S32*Q32 -> 24000
A33: 4 | C33: 재 료 비 | G33: =(G30+G31+G32) -> 85794 | N33: 검 사 | Q33: 1 | S33: 24000 | U33: =S33*Q33 -> 24000
A34: 5 | C34: 노 무 비 | G34: =U38 -> 72000
A35: 6 | C35: 경 비 | G35: =G34*0.1 -> 7200
A36: 7 | C36: 가공비 | G36: =G34+G35 -> 79200
A37: 8 | B37: 제조원가 | G37: =G33+G36 -> 164994
A38: 9 | B38: 재료관리비 | G38: =((G30*0.01)+(G31*0.01)+(G32*0.02)) -> 857.94 | U38: =SUM(U31:V37) -> 72000
A39: 10 | B39: 판매 / 관리비 | G39: =G36*0.15 -> 11880 | M39: 특기사항
A40: 11 | B40: 이 윤 | G40: =(G36+G39)*0.15 -> 13662
A41: 12 | B41: 운반비 / PLT | G41: 0
...

Sheet FDI
A1: PROJ. 명 | C1: =총합계!C1 -> 덴버전동차 50량 | J1: 원가견적/조사서(갑) - ASSY 用 - | T1: 회 사 명 (코드) | X1: 주) 우 진 산 전
A2: 차 종 | T2: =총합계!T2 -> 2011 년 4 월 11 일
A3: 품 번 | J3: 수 량 | N3: 50 | T3: 결 재 | U3: 담 당 | W3: 과장 | Y3: 팀장 | AA3: 임원
A5: 품 명 | C5: FDI | J5: 도 면 NO
A6: 구 성 부 품 비 명 세 | B6: NO | C6: 부 번 | G6: 부 품 명 | M6: 단 위 | N6: 수 량 | O6: 단 가 | Q6: 견 적 가 | W6: 조사가 | AD6: * Glenair 컨넥터 가격 상승 및 Type 변경(ITS -> ITH)
Q7: 자작 | S7: 외주 | U7: 수입 | W7: 자작 | Y7: 외주 | AA7: 수입 | AD7: * Power Module 가격 상승.
B8: 1 | C8: CPU BOARD | G8: ASS'Y(ANTS) | M8: EA | N8: 1 | O8: =216000*1.5 -> 324000 | S8: =N8*O8 -> 324000 | AC8: =ROUND(O8*1.1,-2) -> 356400 | AD8: *LED 가격 상승.
B9: 2 | G9: LED SENSOR(ANTS) | M9: EA | N9: 1 | O9: 16200 | S9: =N9*O9 -> 16200 | AC9: =ROUND(O9*1.1,-2) -> 17800
B10: 3 | C10: POWER UNIT | G10: AC230V/5V(이즈파워) | M10: EA | N10: 1 | O10: 1632000 | S10: =N10*O10 -> 1632000 | AC10: =ROUND(O10*1.1,-2) -> 1795200
B11: 4 | C11: FRAME BOX | G11: ASS'Y(보성엔지니어) | M11: EA | N11: 1 | O11: 155250 | S11: =N11*O11 -> 155250 | AC11: =ROUND(O11*1.1,-2) -> 170800
B12: 5 | C12: CONNECTOR | G12: Glenair ASS'Y(넥서스) | M12: EA | N12: 1 | O12: 138000 | S12: =N12*O12 -> 138000 | AC12: =ROUND(O12*1.1,-2) -> 151800
B13: 6 | C13: LED-단색 | G13: ASS'Y(오디텍) | M13: EA | N13: 10 | O13: 58050 | S13: =N13*O13 -> 580500 | AC13: =ROUND(O13*1.1,-2) -> 63900
B14: 7 | C14: LED-칼라 | G14: ASS'Y(오디텍) | M14: EA | N14: 2 | O14: 233550 | S14: =N14*O14 -> 467100 | AC14: =ROUND(O14*1.1,-2) -> 256900
B15: 8 | C15: 부자재 | G15: 기타 Connector 및 전선(은강반도체) | M15: EA | N15: 1 | O15: 120000 | S15: =N15*O15 -> 120000 | AC15: =ROUND(O15*1.1,-2) -> 132000
B16: 9 | C16: MAX1480ECEPI | G16: ASS'Y(위니프로) | M16: EA | N16: 1 | O16: 33750 | S16: =N16*O16 -> 33750 | AC16: =ROUND(O16*1.1,-2) -> 37100
B17: 10 | AC17: =ROUND(O17*1.1,-2) -> 0
B18: 11 | AC18: =ROUND(O18*1.1,-2) -> 0
B19: 12 | AC19: =ROUND(O19*1.1,-2) -> 0
B20: 13 | AC20: =ROUND(O20*1.1,-2) -> 0
B21: 14 | AC21: =ROUND(O21*1.1,-2) -> 0
B22: 15 | AC22: =ROUND(O22*1.1,-2) -> 0
B23: 16 | AC23: =ROUND(O23*1.1,-2) -> 0
B24: 17 | AC24: =ROUND(O24*1.1,-2) -> 0
B25: 18 | AC25: =ROUND(O25*1.1,-2) -> 0
B26: 19 | AC26: =ROUND(O26*1.1,-2) -> 0
B27: 20
Q28: =SUM(Q8:R27) -> 0 | S28: =SUM(S8:T27) -> 3466800 | U28: =SUM(U8:V27) -> 0
A29: 원 가 항 목 | G29: 견 적 가 | J29: 조 사 가 | M29: 종 합 조 립 가 공 비 명 세 | N29: 공 정 명 | Q29: 조립시간 (HR) | S29: 가동임율 (￦/HR) | U29: 조립 가공비 | W29: 조립시간 (HR) | Y29: 가동임율 (￦/HR) | AA29: 조립 가공비
A30: 1 | C30: 자 작 | G30: =Q28 -> 0
A31: 2 | C31: 외 주 | G31: =S28+S87 -> 3466800 | N31: 기기조립 | Q31: 8 | S31: 24000 | U31: =S31*Q31 -> 192000
A32: 3 | C32: 수 입 | G32: =U28 -> 0 | N32: 기기배선 | Q32: 10 | S32: 24000 | U32: =S32*Q32 -> 240000
A33: 4 | C33: 재 료 비 | G33: =(G30+G31+G32) -> 3466800 | N33: 검 사 | Q33: 5 | S33: 24000 | U33: =S33*Q33 -> 120000
A34: 5 | C34: 노 무 비 | G34: =U38 -> 552000
A35: 6 | C35: 경 비 | G35: =G34*0.1 -> 55200
A36: 7 | C36: 가공비 | G36: =G34+G35 -> 607200
A37: 8 | B37: 제조원가 | G37: =G33+G36 -> 4074000
A38: 9 | B38: 재료관리비 | G38: =((G30*0.01)+(G31*0.01)+(G32*0.02)) -> 34668 | U38: =SUM(U31:V37) -> 552000
A39: 10 | B39: 판매 / 관리비 | G39: =G36*0.15 -> 91080 | M39: 특기사항
A40: 11 | B40: 이 윤 | G40: =(G36+G39)*0.15 -> 104742
A41: 12 | B41: 운반비 / PLT | G41: 0
...

Sheet SDI
A1: PROJ. 명 | C1: =총합계!C1 -> 덴버전동차 50량 | J1: 원가견적/조사서(갑) - ASSY 用 - | T1: 회 사 명 (코드) | X1: 주) 우 진 산 전
A2: 차 종 | T2: =총합계!T2 -> 2011 년 4 월 11 일
A3: 품 번 | J3: 수 량 | N3: 50 | T3: 결 재 | U3: 담 당 | W3: 과장 | Y3: 팀장 | AA3: 임원
A5: 품 명 | C5: SDI | J5: 도 면 NO
A6: 구 성 부 품 비 명 세 | B6: NO | C6: 부 번 | G6: 부 품 명 | M6: 단 위 | N6: 수 량 | O6: 단 가 | Q6: 견 적 가 | W6: 조사가 | AD6: * Glenair 컨넥터 가격 상승 및 Type 변경(ITS -> ITH)
Q7: 자작 | S7: 외주 | U7: 수입 | W7: 자작 | Y7: 외주 | AA7: 수입 | AD7: * Power Module 가격 상승.
B8: 1 | C8: CPU BOARD | G8: ASS'Y(ANTS) | M8: EA | N8: 1 | O8: =216000*1.5 -> 324000 | S8: =N8*O8 -> 324000 | AC8: =ROUND(O8*1.1,-2) -> 356400 | AD8: *LED 가격 상승.
B9: 2 | C9: ASS'Y | G9: LED SENSOR(ANTS) | M9: EA | N9: 1 | O9: 16200 | S9: =N9*O9 -> 16200 | AC9: =ROUND(O9*1.1,-2) -> 17800
B10: 3 | C10: POWER UNIT | G10: AC230V/5V(이즈파워) | M10: EA | N10: 1 | O10: 1632000 | S10: =N10*O10 -> 1632000 | AC10: =ROUND(O10*1.1,-2) -> 1795200
B11: 4 | C11: FRAME BOX | G11: ASS'Y(보성엔지니어) | M11: EA | N11: 1 | O11: 155250 | S11: =N11*O11 -> 155250 | AC11: =ROUND(O11*1.1,-2) -> 170800
B12: 5 | C12: CONNECTOR | G12: Glenair ASS'Y(넥서스) | M12: EA | N12: 1 | O12: 138000 | S12: =N12*O12 -> 138000 | AC12: =ROUND(O12*1.1,-2) -> 151800
B13: 6 | C13: LED-단색 | G13: ASS'Y(오디텍) | M13: EA | N13: 8 | O13: 58050 | S13: =N13*O13 -> 464400 | AC13: =ROUND(O13*1.1,-2) -> 63900
B14: 7 | C14: LED-칼라 | G14: ASS'Y(오디텍) | M14: EA | N14: 1 | O14: 233550 | S14: =N14*O14 -> 233550 | AC14: =ROUND(O14*1.1,-2) -> 256900
B15: 8 | C15: 부자재 | G15: 기타 Connector 및 전선(은강반도체) | M15: EA | N15: 1 | O15: 120000 | S15: =N15*O15 -> 120000 | AC15: =ROUND(O15*1.1,-2) -> 132000
B16: 9 | C16: MAX1480ECEPI | G16: ASS'Y(위니프로) | M16: EA | N16: 1 | O16: 33750 | S16: =N16*O16 -> 33750 | AC16: =ROUND(O16*1.1,-2) -> 37100
B17: 10 | AC17: =ROUND(O17*1.1,-2) -> 0
B18: 11 | AC18: =ROUND(O18*1.1,-2) -> 0
B19: 12 | AC19: =ROUND(O19*1.1,-2) -> 0
B20: 13 | AC20: =ROUND(O20*1.1,-2) -> 0
B21: 14 | AC21: =ROUND(O21*1.1,-2) -> 0
B22: 15
B23: 16
B24: 17
B25: 18
B26: 19
B27: 20
Q28: =SUM(Q8:R27) -> 0 | S28: =SUM(S8:T27) -> 3117150 | U28: =SUM(U8:V27) -> 0
A29: 원 가 항 목 | G29: 견 적 가 | J29: 조 사 가 | M29: 종 합 조 립 가 공 비 명 세 | N29: 공 정 명 | Q29: 조립시간 (HR) | S29: 가동임율 (￦/HR) | U29: 조립 가공비 | W29: 조립시간 (HR) | Y29: 가동임율 (￦/HR) | AA29: 조립 가공비
A30: 1 | C30: 자 작 | G30: =Q28 -> 0
A31: 2 | C31: 외 주 | G31: =S28+S87 -> 3117150 | N31: 기기조립 | Q31: 8 | S31: 24000 | U31: =S31*Q31 -> 192000
A32: 3 | C32: 수 입 | G32: =U28 -> 0 | N32: 기기배선 | Q32: 10 | S32: 24000 | U32: =S32*Q32 -> 240000
A33: 4 | C33: 재 료 비 | G33: =(G30+G31+G32) -> 3117150 | N33: 검 사 | Q33: 5 | S33: 24000 | U33: =S33*Q33 -> 120000
A34: 5 | C34: 노 무 비 | G34: =U38 -> 552000
A35: 6 | C35: 경 비 | G35: =G34*0.1 -> 55200
A36: 7 | C36: 가공비 | G36: =G34+G35 -> 607200
A37: 8 | B37: 제조원가 | G37: =G33+G36 -> 3724350
A38: 9 | B38: 재료관리비 | G38: =((G30*0.01)+(G31*0.01)+(G32*0.02)) -> 31171.5 | U38: =SUM(U31:V37) -> 552000
A39: 10 | B39: 판매 / 관리비 | G39: =G36*0.15 -> 91080 | M39: 특기사항
A40: 11 | B40: 이 윤 | G40: =(G36+G39)*0.15 -> 104742
A41: 12 | B41: 운반비 / PLT | G41: 0
...

Sheet PII
A1: PROJ. 명 | C1: =총합계!C1 -> 덴버전동차 50량 | J1: 원가견적/조사서(갑) - ASSY 用 - | T1: 회 사 명 (코드) | X1: 주) 우 진 산 전
A2: 차 종 | T2: =총합계!T2 -> 2011 년 4 월 11 일
A3: 품 번 | J3: 수 량 | N3: 50 | T3: 결 재 | U3: 담 당 | W3: 과장 | Y3: 팀장 | AA3: 임원
A5: 품 명 | C5: PII | J5: 도 면 NO
A6: 구 성 부 품 비 명 세 | B6: NO | C6: 부 번 | G6: 부 품 명 | M6: 단 위 | N6: 수 량 | O6: 단 가 | Q6: 견 적 가 | W6: 조사가
Q7: 자작 | S7: 외주 | U7: 수입 | W7: 자작 | Y7: 외주 | AA7: 수입
B8: 1 | C8: CPU BOARD | G8: ASS'Y(ANTS) | M8: EA | N8: 1 | O8: 324000 | S8: =N8*O8 -> 324000 | AC8: =ROUND(O8*1.1,-2) -> 356400
B9: 2 | C9: POWER UNIT | G9: DC37.5V/5V(이즈파워) | M9: EA | N9: 1 | O9: 1000000 | S9: =N9*O9 -> 1000000 | AC9: =ROUND(O9*1.1,-2) -> 1100000
B10: 3 | C10: FRAME BOX | G10: ASS'Y(보성엔지니어) | M10: EA | N10: 1 | O10: 206550 | S10: =N10*O10 -> 206550 | AC10: =ROUND(O10*1.1,-2) -> 227200
B11: 4 | C11: CONNECTOR | G11: Glenair ASS'Y(넥서스) | M11: EA | N11: 1 | O11: 137931 | S11: =N11*O11 -> 137931 | AC11: =ROUND(O11*1.1,-2) -> 151700
B12: 5 | C12: LED-단색 | G12: ASS'Y(오디텍) | M12: EA | N12: 8 | O12: 64800 | S12: =N12*O12 -> 518400 | AC12: =ROUND(O12*1.1,-2) -> 71300
B13: 6 | C13: 부자재 | G13: 기타 Connector 및 전선(은강반도체) | M13: EA | N13: 1 | O13: 120000 | S13: =N13*O13 -> 120000 | AC13: =ROUND(O13*1.1,-2) -> 132000
B14: 7 | C14: MAX1480ECEPI | G14: ASS'Y(위니프로) | M14: EA | N14: 1 | O14: 33750 | S14: =N14*O14 -> 33750 | AC14: =ROUND(O14*1.1,-2) -> 37100
B15: 8 | AC15: =ROUND(O15*1.1,-2) -> 0
B16: 9 | AC16: =ROUND(O16*1.1,-2) -> 0
B17: 10 | AC17: =ROUND(O17*1.1,-2) -> 0
B18: 11 | AC18: =ROUND(O18*1.1,-2) -> 0
B19: 12 | AC19: =ROUND(O19*1.1,-2) -> 0
B20: 13 | AC20: =ROUND(O20*1.1,-2) -> 0
B21: 14 | AC21: =ROUND(O21*1.1,-2) -> 0
B22: 15 | AC22: =ROUND(O22*1.1,-2) -> 0
B23: 16 | AC23: =ROUND(O23*1.1,-2) -> 0
B24: 17 | AC24: =ROUND(O24*1.1,-2) -> 0
B25: 18 | AC25: =ROUND(O25*1.1,-2) -> 0
B26: 19 | AC26: =ROUND(O26*1.1,-2) -> 0
B27: 20 | AC27: =ROUND(O27*1.1,-2) -> 0
Q28: =SUM(Q8:R27) -> 0 | S28: =SUM(S8:T27) -> 2340631 | U28: =SUM(U8:V27) -> 0 | AC28: =ROUND(O28*1.1,-2) -> 0
A29: 원 가 항 목 | G29: 견 적 가 | J29: 조 사 가 | M29: 종 합 조 립 가 공 비 명 세 | N29: 공 정 명 | Q29: 조립시간 (HR) | S29: 가동임율 (￦/HR) | U29: 조립 가공비 | W29: 조립시간 (HR) | Y29: 가동임율 (￦/HR) | AA29: 조립 가공비 | AC29: =ROUND(O29*1.1,-2) -> 0
A30: 1 | C30: 자 작 | G30: =Q28 -> 0 | AC30: =ROUND(O30*1.1,-2) -> 0
A31: 2 | C31: 외 주 | G31: =S28+S87 -> 2340631 | N31: 기기조립 | Q31: 8 | S31: 24000 | U31: =S31*Q31 -> 192000 | AC31: =ROUND(O31*1.1,-2) -> 0
A32: 3 | C32: 수 입 | G32: =U28 -> 0 | N32: 기기배선 | Q32: 10 | S32: 24000 | U32: =S32*Q32 -> 240000 | AC32: =ROUND(O32*1.1,-2) -> 0
A33: 4 | C33: 재 료 비 | G33: =(G30+G31+G32) -> 2340631 | N33: 검 사 | Q33: 5 | S33: 24000 | U33: =S33*Q33 -> 120000 | AC33: =ROUND(O33*1.1,-2) -> 0
A34: 5 | C34: 노 무 비 | G34: =U38 -> 552000 | AC34: =ROUND(O34*1.1,-2) -> 0
A35: 6 | C35: 경 비 | G35: =G34*0.1 -> 55200 | AC35: =ROUND(O35*1.1,-2) -> 0
A36: 7 | C36: 가공비 | G36: =G34+G35 -> 607200 | AC36: =ROUND(O36*1.1,-2) -> 0
A37: 8 | B37: 제조원가 | G37: =G33+G36 -> 2947831 | AC37: =ROUND(O37*1.1,-2) -> 0
A38: 9 | B38: 재료관리비 | G38: =((G30*0.01)+(G31*0.01)+(G32*0.02)) -> 23406.31 | U38: =SUM(U31:V37) -> 552000 | AC38: =ROUND(O38*1.1,-2) -> 0
A39: 10 | B39: 판매 / 관리비 | G39: =G36*0.15 -> 91080 | M39: 특기사항 | AC39: =ROUND(O39*1.1,-2) -> 0
A40: 11 | B40: 이 윤 | G40: =(G36+G39)*0.15 -> 104742 | AC40: =ROUND(O40*1.1,-2) -> 0
A41: 12 | B41: 운반비 / PLT | G41: 0 | AC41: =ROUND(O41*1.1,-2) -> 0
...

Sheet PID
A1: PROJ. 명 | C1: =총합계!C1 -> 덴버전동차 50량 | J1: 원가견적/조사서(갑) - ASSY 用 - | T1: 회 사 명 (코드) | X1: 주) 우 진 산 전
A2: 차 종 | T2: =총합계!T2 -> 2011 년 4 월 11 일
A3: 품 번 | J3: 수 량 | N3: 50 | T3: 결 재 | U3: 담 당 | W3: 과장 | Y3: 팀장 | AA3: 임원
A5: 품 명 | C5: PID | J5: 도 면 NO
A6: 구 성 부 품 비 명 세 | B6: NO | C6: 부 번 | G6: 부 품 명 | M6: 단 위 | N6: 수 량 | O6: 단 가 | Q6: 견 적 가 | W6: 조사가 | AD6: * LCD 가격 상승 요인.
Q7: 자작 | S7: 외주 | U7: 수입 | W7: 자작 | Y7: 외주 | AA7: 수입 | AD7: * Glenair 컨넥터 가격 상승 및 Type 변경(ITS -> ITH)
B8: 1 | C8: CPU BOARD | G8: ASS'Y(ANTS) | M8: EA | N8: 1 | O8: 550000 | S8: =N8*O8 -> 550000 | AC8: =ROUND(O8*1.1,-2) -> 605000 | AD8: * 엠비 콘넥터 가격 상승
B9: 2 | C9: POWER UNIT | G9: AC230V/5V(이즈파워) | M9: EA | N9: 1 | O9: 1632000 | S9: =N9*O9 -> 1632000 | AC9: =ROUND(O9*1.1,-2) -> 1795200 | AD9: * Power Module 가격 상승.
B10: 3 | C10: FRAME BOX | G10: ASS'Y(보성엔지니어) | M10: EA | N10: 1 | O10: 283500 | S10: =N10*O10 -> 283500 | AC10: =ROUND(O10*1.1,-2) -> 311900 | AD10: * PCB에 동영상 Bypass 기능 추가
B11: 4 | C11: CONNECTOR | G11: Glenair ASS'Y(넥서스) | M11: EA | N11: 1 | O11: 62281 | S11: =N11*O11 -> 62281 | AC11: =ROUND(O11*1.1,-2) -> 68500
B12: 5 | G12: AMP(엠비콘넥터) | M12: EA | N12: 1 | O12: 41850 | S12: =N12*O12 -> 41850 | AC12: =ROUND(O12*1.1,-2) -> 46000
B13: 6 | C13: TFT-LCD ASS'Y | G13: ASS'Y(i-Tech) | M13: EA | N13: 1 | O13: 337500 | S13: =N13*O13 -> 337500 | AC13: =ROUND(O13*1.1,-2) -> 371300
B14: 7 | C14: 부자재 | G14: 기타 Connector 및 전선(은강반도체) | M14: EA | N14: 1 | O14: 120000 | S14: =N14*O14 -> 120000 | AC14: =ROUND(O14*1.1,-2) -> 132000
B15: 8 | C15: MAX1480ECEPI | G15: ASS'Y(위니프로) | M15: EA | N15: 1 | O15: 33750 | S15: =N15*O15 -> 33750 | AC15: =ROUND(O15*1.1,-2) -> 37100
B16: 9 | AC16: =ROUND(O16*1.1,-2) -> 0
B17: 10 | AC17: =ROUND(O17*1.1,-2) -> 0
B18: 11 | AC18: =ROUND(O18*1.1,-2) -> 0
B19: 12 | AC19: =ROUND(O19*1.1,-2) -> 0
B20: 13 | AC20: =ROUND(O20*1.1,-2) -> 0
B21: 14 | AC21: =ROUND(O21*1.1,-2) -> 0
B22: 15 | AC22: =ROUND(O22*1.1,-2) -> 0
B23: 16 | AC23: =ROUND(O23*1.1,-2) -> 0
B24: 17 | AC24: =ROUND(O24*1.1,-2) -> 0
B25: 18 | AC25: =ROUND(O25*1.1,-2) -> 0
B26: 19 | AC26: =ROUND(O26*1.1,-2) -> 0
B27: 20 | AC27: =ROUND(O27*1.1,-2) -> 0
Q28: =SUM(Q8:R27) -> 0 | S28: =SUM(S8:T27) -> 3060881 | U28: =SUM(U8:V27) -> 0 | AC28: =ROUND(O28*1.1,-2) -> 0
A29: 원 가 항 목 | G29: 견 적 가 | J29: 조 사 가 | M29: 종 합 조 립 가 공 비 명 세 | N29: 공 정 명 | Q29: 조립시간 (HR) | S29: 가동임율 (￦/HR) | U29: 조립 가공비 | W29: 조립시간 (HR) | Y29: 가동임율 (￦/HR) | AA29: 조립 가공비 | AC29: =ROUND(O29*1.1,-2) -> 0
A30: 1 | C30: 자 작 | G30: =Q28 -> 0 | AC30: =ROUND(O30*1.1,-2) -> 0
A31: 2 | C31: 외 주 | G31: =S28+S87 -> 3060881 | N31: 기기조립 | Q31: 8 | S31: 24000 | U31: =S31*Q31 -> 192000 | AC31: =ROUND(O31*1.1,-2) -> 0
A32: 3 | C32: 수 입 | G32: =U28 -> 0 | N32: 기기배선 | Q32: 10 | S32: 24000 | U32: =S32*Q32 -> 240000 | AC32: =ROUND(O32*1.1,-2) -> 0
A33: 4 | C33: 재 료 비 | G33: =(G30+G31+G32) -> 3060881 | N33: 검 사 | Q33: 5 | S33: 24000 | U33: =S33*Q33 -> 120000 | AC33: =ROUND(O33*1.1,-2) -> 0
A34: 5 | C34: 노 무 비 | G34: =U38 -> 552000 | AC34: =ROUND(O34*1.1,-2) -> 0
A35: 6 | C35: 경 비 | G35: =G34*0.1 -> 55200 | AC35: =ROUND(O35*1.1,-2) -> 0
A36: 7 | C36: 가공비 | G36: =G34+G35 -> 607200 | AC36: =ROUND(O36*1.1,-2) -> 0
A37: 8 | B37: 제조원가 | G37: =G33+G36 -> 3668081 | AC37: =ROUND(O37*1.1,-2) -> 0
A38: 9 | B38: 재료관리비 | G38: =((G30*0.01)+(G31*0.01)+(G32*0.02)) -> 30608.81 | U38: =SUM(U31:V37) -> 552000 | AC38: =ROUND(O38*1.1,-2) -> 0
A39: 10 | B39: 판매 / 관리비 | G39: =G36*0.15 -> 91080 | M39: 특기사항 | AC39: =ROUND(O39*1.1,-2) -> 0
A40: 11 | B40: 이 윤 | G40: =(G36+G39)*0.15 -> 104742 | AC40: =ROUND(O40*1.1,-2) -> 0
A41: 12 | B41: 운반비 / PLT | G41: 0 | AC41: =ROUND(O41*1.1,-2) -> 0
...

Sheet JCR1
A1: PROJ. 명 | C1: =총합계!C1 -> 덴버전동차 50량 | J1: 원가견적/조사서(갑) - ASSY 用 - | T1: 회 사 명 (코드) | X1: 주) 우 진 산 전
A2: 차 종 | T2: =총합계!T2 -> 2011 년 4 월 11 일
A3: 품 번 | J3: 수 량 | N3: 50 | T3: 결 재 | U3: 담 당 | W3: 과장 | Y3: 팀장 | AA3: 임원
A5: 품 명 | C5: JCR1 | J5: 도 면 NO
A6: 구 성 부 품 비 명 세 | B6: NO | C6: 부 번 | G6: 부 품 명 | M6: 단 위 | N6: 수 량 | O6: 단 가 | Q6: 견 적 가 | W6: 조사가
Q7: 자작 | S7: 외주 | U7: 수입 | W7: 자작 | Y7: 외주 | AA7: 수입
B8: 1 | C8: JUMPER PLUG ASS'Y | G8: ASS'Y(햄머) | M8: EA | N8: 1 | O8: =1744200*1.5 -> 2616300 | S8: =N8*O8 -> 2616300 | AC8: =ROUND(O8*1.1,-2) -> 2877900 | AD8: * 컨넥터 가격 상승
B9: 2 | S9: =N9*O9 -> 0 | AC9: =ROUND(O9*1.1,-2) -> 0
B10: 3 | S10: =N10*O10 -> 0 | AC10: =ROUND(O10*1.1,-2) -> 0
B11: 4 | S11: =N11*O11 -> 0 | AC11: =ROUND(O11*1.1,-2) -> 0
B12: 5 | S12: =N12*O12 -> 0 | AC12: =ROUND(O12*1.1,-2) -> 0
B13: 6 | S13: =N13*O13 -> 0 | AC13: =ROUND(O13*1.1,-2) -> 0
B14: 7 | S14: =N14*O14 -> 0 | AC14: =ROUND(O14*1.1,-2) -> 0
B15: 8 | AC15: =ROUND(O15*1.1,-2) -> 0
B16: 9 | AC16: =ROUND(O16*1.1,-2) -> 0
B17: 10 | AC17: =ROUND(O17*1.1,-2) -> 0
B18: 11 | AC18: =ROUND(O18*1.1,-2) -> 0
B19: 12 | AC19: =ROUND(O19*1.1,-2) -> 0
B20: 13 | AC20: =ROUND(O20*1.1,-2) -> 0
B21: 14 | AC21: =ROUND(O21*1.1,-2) -> 0
B22: 15 | AC22: =ROUND(O22*1.1,-2) -> 0
B23: 16 | AC23: =ROUND(O23*1.1,-2) -> 0
B24: 17 | AC24: =ROUND(O24*1.1,-2) -> 0
B25: 18 | AC25: =ROUND(O25*1.1,-2) -> 0
B26: 19 | AC26: =ROUND(O26*1.1,-2) -> 0
B27: 20 | AC27: =ROUND(O27*1.1,-2) -> 0
Q28: =SUM(Q8:R27) -> 0 | S28: =SUM(S8:T27) -> 2616300 | U28: =SUM(U8:V27) -> 0 | AC28: =ROUND(O28*1.1,-2) -> 0
A29: 원 가 항 목 | G29: 견 적 가 | J29: 조 사 가 | M29: 종 합 조 립 가 공 비 명 세 | N29: 공 정 명 | Q29: 조립시간 (HR) | S29: 가동임율 (￦/HR) | U29: 조립 가공비 | W29: 조립시간 (HR) | Y29: 가동임율 (￦/HR) | AA29: 조립 가공비 | AC29: =ROUND(O29*1.1,-2) -> 0
A30: 1 | C30: 자 작 | G30: =Q28 -> 0 | AC30: =ROUND(O30*1.1,-2) -> 0
A31: 2 | C31: 외 주 | G31: =S28+S87 -> 2616300 | N31: 기기조립 | S31: 24000 | U31: =S31*Q31 -> 0 | AC31: =ROUND(O31*1.1,-2) -> 0
A32: 3 | C32: 수 입 | G32: =U28 -> 0 | N32: 기기배선 | S32: 24000 | U32: =S32*Q32 -> 0 | AC32: =ROUND(O32*1.1,-2) -> 0
A33: 4 | C33: 재 료 비 | G33: =(G30+G31+G32) -> 2616300 | N33: 검 사 | Q33: 2 | S33: 24000 | U33: =S33*Q33 -> 48000 | AC33: =ROUND(O33*1.1,-2) -> 0
A34: 5 | C34: 노 무 비 | G34: =U38 -> 48000 | AC34: =ROUND(O34*1.1,-2) -> 0
A35: 6 | C35: 경 비 | G35: =G34*0.1 -> 4800 | AC35: =ROUND(O35*1.1,-2) -> 0
A36: 7 | C36: 가공비 | G36: =G34+G35 -> 52800 | AC36: =ROUND(O36*1.1,-2) -> 0
A37: 8 | B37: 제조원가 | G37: =G33+G36 -> 2669100 | AC37: =ROUND(O37*1.1,-2) -> 0
A38: 9 | B38: 재료관리비 | G38: =((G30*0.01)+(G31*0.01)+(G32*0.02)) -> 26163 | U38: =SUM(U31:V37) -> 48000 | AC38: =ROUND(O38*1.1,-2) -> 0
A39: 10 | B39: 판매 / 관리비 | G39: =G36*0.15 -> 7920 | M39: 특기사항 | AC39: =ROUND(O39*1.1,-2) -> 0
A40: 11 | B40: 이 윤 | G40: =(G36+G39)*0.15 -> 9108 | AC40: =ROUND(O40*1.1,-2) -> 0
A41: 12 | B41: 운반비 / PLT | G41: 0 | AC41: =ROUND(O41*1.1,-2) -> 0
...

Sheet CBL1
A1: PROJ. 명 | C1: =총합계!C1 -> 덴버전동차 50량 | J1: 원가견적/조사서(갑) - ASSY 用 - | T1: 회 사 명 (코드) | X1: 주) 우 진 산 전
A2: 차 종 | T2: =총합계!T2 -> 2011 년 4 월 11 일
A3: 품 번 | J3: 수 량 | N3: 50 | T3: 결 재 | U3: 담 당 | W3: 과장 | Y3: 팀장 | AA3: 임원
A5: 품 명 | C5: CBL1 | J5: 도 면 NO
A6: 구 성 부 품 비 명 세 | B6: NO | C6: 부 번 | G6: 부 품 명 | M6: 단 위 | N6: 수 량 | O6: 단 가 | Q6: 견 적 가 | W6: 조사가 | AD6: * 동영상 백업 기능 추가에 다른 COAXIAL CABLE ASS'Y 길이 추가
Q7: 자작 | S7: 외주 | U7: 수입 | W7: 자작 | Y7: 외주 | AA7: 수입 | AD7: * BNC 컨넥터는 1량 기준으로 가격 산정.
B8: 1 | C8: COAXIAL CABLE ASS'Y | G8: ASS'Y(m단위)(햄머) | M8: EA | N8: 150 | O8: 11000 | S8: =N8*O8 -> 1650000 | AC8: =ROUND(O8*1.1,-2) -> 12100 | AD8: * Glenair 컨넥터 가격 상승 및 Type 변경(ITS -> ITH)
B9: 2 | G9: BNC CONNECTOR(햄머) | M9: EA | N9: 1 | O9: 190000 | S9: =N9*O9 -> 190000 | AC9: =ROUND(O9*1.1,-2) -> 209000
B10: 3 | G10: BAYONET CONNECTOR(넥서스) | M10: EA | N10: 1 | O10: 4924848 | S10: =N10*O10 -> 4924848 | AC10: =ROUND(O10*1.1,-2) -> 5417300
B11: 4 | S11: =N11*O11 -> 0 | AC11: =ROUND(O11*1.1,-2) -> 0
B12: 5 | S12: =N12*O12 -> 0 | AC12: =ROUND(O12*1.1,-2) -> 0
B13: 6 | S13: =N13*O13 -> 0 | AC13: =ROUND(O13*1.1,-2) -> 0
B14: 7 | S14: =N14*O14 -> 0 | AC14: =ROUND(O14*1.1,-2) -> 0
B15: 8 | AC15: =ROUND(O15*1.1,-2) -> 0
B16: 9 | AC16: =ROUND(O16*1.1,-2) -> 0
B17: 10 | AC17: =ROUND(O17*1.1,-2) -> 0
B18: 11 | AC18: =ROUND(O18*1.1,-2) -> 0
B19: 12 | AC19: =ROUND(O19*1.1,-2) -> 0
B20: 13 | AC20: =ROUND(O20*1.1,-2) -> 0
B21: 14 | AC21: =ROUND(O21*1.1,-2) -> 0
B22: 15 | AC22: =ROUND(O22*1.1,-2) -> 0
B23: 16 | AC23: =ROUND(O23*1.1,-2) -> 0
B24: 17 | AC24: =ROUND(O24*1.1,-2) -> 0
B25: 18 | AC25: =ROUND(O25*1.1,-2) -> 0
B26: 19 | AC26: =ROUND(O26*1.1,-2) -> 0
B27: 20 | AC27: =ROUND(O27*1.1,-2) -> 0
Q28: =SUM(Q8:R27) -> 0 | S28: =SUM(S8:T27) -> 6764848 | U28: =SUM(U8:V27) -> 0 | AC28: =ROUND(O28*1.1,-2) -> 0
A29: 원 가 항 목 | G29: 견 적 가 | J29: 조 사 가 | M29: 종 합 조 립 가 공 비 명 세 | N29: 공 정 명 | Q29: 조립시간 (HR) | S29: 가동임율 (￦/HR) | U29: 조립 가공비 | W29: 조립시간 (HR) | Y29: 가동임율 (￦/HR) | AA29: 조립 가공비 | AC29: =ROUND(O29*1.1,-2) -> 0
A30: 1 | C30: 자 작 | G30: =Q28 -> 0 | AC30: =ROUND(O30*1.1,-2) -> 0
A31: 2 | C31: 외 주 | G31: =S28+S87 -> 6764848 | AC31: =ROUND(O31*1.1,-2) -> 0
A32: 3 | C32: 수 입 | G32: =U28 -> 0 | AC32: =ROUND(O32*1.1,-2) -> 0
A33: 4 | C33: 재 료 비 | G33: =(G30+G31+G32) -> 6764848 | AC33: =ROUND(O33*1.1,-2) -> 0
A34: 5 | C34: 노 무 비 | G34: =U38 -> 0 | AC34: =ROUND(O34*1.1,-2) -> 0
A35: 6 | C35: 경 비 | G35: =G34*0.1 -> 0 | AC35: =ROUND(O35*1.1,-2) -> 0
A36: 7 | C36: 가공비 | G36: =G34+G35 -> 0 | AC36: =ROUND(O36*1.1,-2) -> 0
A37: 8 | B37: 제조원가 | G37: =G33+G36 -> 6764848 | AC37: =ROUND(O37*1.1,-2) -> 0
A38: 9 | B38: 재료관리비 | G38: =((G30*0.01)+(G31*0.01)+(G32*0.02)) -> 67648.48 | U38: =SUM(U31:V37) -> 0 | AC38: =ROUND(O38*1.1,-2) -> 0
A39: 10 | B39: 판매 / 관리비 | G39: =G36*0.15 -> 0 | M39: 특기사항 | AC39: =ROUND(O39*1.1,-2) -> 0
A40: 11 | B40: 이 윤 | G40: =(G36+G39)*0.15 -> 0 | AC40: =ROUND(O40*1.1,-2) -> 0
A41: 12 | B41: 운반비 / PLT | G41: 0 | AC41: =ROUND(O41*1.1,-2) -> 0
...

Sheet JCR2
A1: PROJ. 명 | C1: =총합계!C1 -> 덴버전동차 50량 | J1: 원가견적/조사서(갑) - ASSY 用 - | T1: 회 사 명 (코드) | X1: 주) 우 진 산 전
A2: 차 종 | T2: =총합계!T2 -> 2011 년 4 월 11 일
A3: 품 번 | J3: 수 량 | N3: 50 | T3: 결 재 | U3: 담 당 | W3: 과장 | Y3: 팀장 | AA3: 임원
A5: 품 명 | C5: JCR2 | J5: 도 면 NO
A6: 구 성 부 품 비 명 세 | B6: NO | C6: 부 번 | G6: 부 품 명 | M6: 단 위 | N6: 수 량 | O6: 단 가 | Q6: 견 적 가 | W6: 조사가
Q7: 자작 | S7: 외주 | U7: 수입 | W7: 자작 | Y7: 외주 | AA7: 수입 | AD7: * 컨넥터 가격 상승
B8: 1 | C8: JMPER RE | G8: ASS'Y(햄머) | M8: EA | N8: 1 | O8: =373950*1.2 -> 448740 | S8: =N8*O8 -> 448740 | AC8: =ROUND(O8*1.1,-2) -> 493600
B9: 2 | S9: =N9*O9 -> 0 | AC9: =ROUND(O9*1.1,-2) -> 0
B10: 3 | S10: =N10*O10 -> 0 | AC10: =ROUND(O10*1.1,-2) -> 0
B11: 4 | S11: =N11*O11 -> 0 | AC11: =ROUND(O11*1.1,-2) -> 0
B12: 5 | S12: =N12*O12 -> 0 | AC12: =ROUND(O12*1.1,-2) -> 0
B13: 6 | S13: =N13*O13 -> 0 | AC13: =ROUND(O13*1.1,-2) -> 0
B14: 7 | S14: =N14*O14 -> 0 | AC14: =ROUND(O14*1.1,-2) -> 0
B15: 8 | AC15: =ROUND(O15*1.1,-2) -> 0
B16: 9 | AC16: =ROUND(O16*1.1,-2) -> 0
B17: 10 | AC17: =ROUND(O17*1.1,-2) -> 0
B18: 11 | AC18: =ROUND(O18*1.1,-2) -> 0
B19: 12 | AC19: =ROUND(O19*1.1,-2) -> 0
B20: 13 | AC20: =ROUND(O20*1.1,-2) -> 0
B21: 14 | AC21: =ROUND(O21*1.1,-2) -> 0
B22: 15 | AC22: =ROUND(O22*1.1,-2) -> 0
B23: 16 | AC23: =ROUND(O23*1.1,-2) -> 0
B24: 17 | AC24: =ROUND(O24*1.1,-2) -> 0
B25: 18 | AC25: =ROUND(O25*1.1,-2) -> 0
B26: 19 | AC26: =ROUND(O26*1.1,-2) -> 0
B27: 20 | AC27: =ROUND(O27*1.1,-2) -> 0
Q28: =SUM(Q8:R27) -> 0 | S28: =SUM(S8:T27) -> 448740 | U28: =SUM(U8:V27) -> 0 | AC28: =ROUND(O28*1.1,-2) -> 0
A29: 원 가 항 목 | G29: 견 적 가 | J29: 조 사 가 | M29: 종 합 조 립 가 공 비 명 세 | N29: 공 정 명 | Q29: 조립시간 (HR) | S29: 가동임율 (￦/HR) | U29: 조립 가공비 | W29: 조립시간 (HR) | Y29: 가동임율 (￦/HR) | AA29: 조립 가공비 | AC29: =ROUND(O29*1.1,-2) -> 0
A30: 1 | C30: 자 작 | G30: =Q28 -> 0 | AC30: =ROUND(O30*1.1,-2) -> 0
A31: 2 | C31: 외 주 | G31: =S28+S87 -> 448740 | N31: 검사 | Q31: 1 | S31: 24000 | U31: =Q31*S31 -> 24000 | AC31: =ROUND(O31*1.1,-2) -> 0
A32: 3 | C32: 수 입 | G32: =U28 -> 0 | AC32: =ROUND(O32*1.1,-2) -> 0
A33: 4 | C33: 재 료 비 | G33: =(G30+G31+G32) -> 448740 | AC33: =ROUND(O33*1.1,-2) -> 0
A34: 5 | C34: 노 무 비 | G34: =U38 -> 24000 | AC34: =ROUND(O34*1.1,-2) -> 0
A35: 6 | C35: 경 비 | G35: =G34*0.1 -> 2400 | AC35: =ROUND(O35*1.1,-2) -> 0
A36: 7 | C36: 가공비 | G36: =G34+G35 -> 26400 | AC36: =ROUND(O36*1.1,-2) -> 0
A37: 8 | B37: 제조원가 | G37: =G33+G36 -> 475140 | AC37: =ROUND(O37*1.1,-2) -> 0
A38: 9 | B38: 재료관리비 | G38: =((G30*0.01)+(G31*0.01)+(G32*0.02)) -> 4487.4 | U38: =SUM(U31:V37) -> 24000 | AC38: =ROUND(O38*1.1,-2) -> 0
A39: 10 | B39: 판매 / 관리비 | G39: =G36*0.15 -> 3960 | M39: 특기사항 | AC39: =ROUND(O39*1.1,-2) -> 0
A40: 11 | B40: 이 윤 | G40: =(G36+G39)*0.15 -> 4554 | AC40: =ROUND(O40*1.1,-2) -> 0
A41: 12 | B41: 운반비 / PLT | G41: 0 | AC41: =ROUND(O41*1.1,-2) -> 0
...

Sheet CBL2
A1: PROJ. 명 | C1: =총합계!C1 -> 덴버전동차 50량 | J1: 원가견적/조사서(갑) - ASSY 用 - | T1: 회 사 명 (코드) | X1: 주) 우 진 산 전
A2: 차 종 | T2: =총합계!T2 -> 2011 년 4 월 11 일
A3: 품 번 | J3: 수 량 | N3: 50 | T3: 결 재 | U3: 담 당 | W3: 과장 | Y3: 팀장 | AA3: 임원
